Workbook

Sheet Sheet1
Z1: BM.01/HD.05.04-03
Z2: Ngày hiệu lực: 01/07/2023
B6: BẢNG THEO DÕI THÔNG SỐ VẬN HÀNH MÁY NGHIỀN
A7: Hạng mục | C7: Kíp …… Ngày …… tháng …… năm 20…… | O7: Kíp …… Ngày …… tháng …… năm 20……
C8: 0.33333333 | D8: 0.375 | E8: 0.41666667 | F8: 0.45833333 | G8: 0.5 | H8: 0.54166667 | I8: 0.58333333 | J8: 0.625 | K8: 0.66666667 | L8: 0.70833333 | M8: 0.75 | N8: 0.79166667 | O8: 0.83333333 | P8: 0.875 | Q8: 0.91666667 | R8: 0.95833333 | S8: 1 | T8: 1.0416667 | U8: 1.0833333 | V8: 1.125 | W8: 1.1666667 | X8: 1.2083333 | Y8: 1.25 | Z8: 1.2916667
A9: Máy nghiền 1A | B9: Nhiệt độ gối đỡ trước | C9: =Sheet2!D6 -> 0 | D9: =Sheet2!E6 -> 0 | E9: =Sheet2!F6 -> 0 | F9: =Sheet2!G6 -> 0 | G9: =Sheet2!H6 -> 0 | H9: =Sheet2!I6 -> 0 | I9: =Sheet2!J6 -> 0 | J9: =Sheet2!K6 -> 0 | ... Z9: =Sheet2!AA6 -> 0
B10: Nhiệt độ gối đỡ sau | C10: =Sheet2!D7 -> 0 | D10: =Sheet2!E7 -> 0 | E10: =Sheet2!F7 -> 0 | F10: =Sheet2!G7 -> 0 | G10: =Sheet2!H7 -> 0 | H10: =Sheet2!I7 -> 0 | I10: =Sheet2!J7 -> 0 | J10: =Sheet2!K7 -> 0 | ... Z10: =Sheet2!AA7 -> 0
B11: Nhiệt độ cuộn dây A | C11: =Sheet2!D8 -> 0 | D11: =Sheet2!E8 -> 0 | E11: =Sheet2!F8 -> 0 | F11: =Sheet2!G8 -> 0 | G11: =Sheet2!H8 -> 0 | H11: =Sheet2!I8 -> 0 | I11: =Sheet2!J8 -> 0 | J11: =Sheet2!K8 -> 0 | ... Z11: =Sheet2!AA8 -> 0
B12: Nhiệt độ cuộn dây B | C12: =Sheet2!D9 -> 0 | D12: =Sheet2!E9 -> 0 | E12: =Sheet2!F9 -> 0 | F12: =Sheet2!G9 -> 0 | G12: =Sheet2!H9 -> 0 | H12: =Sheet2!I9 -> 0 | I12: =Sheet2!J9 -> 0 | J12: =Sheet2!K9 -> 0 | ... Z12: =Sheet2!AA9 -> 0
B13: Nhiệt độ cuộn dây C | C13: =Sheet2!D10 -> 0 | D13: =Sheet2!E10 -> 0 | E13: =Sheet2!F10 -> 0 | F13: =Sheet2!G10 -> 0 | G13: =Sheet2!H10 -> 0 | H13: =Sheet2!I10 -> 0 | I13: =Sheet2!J10 -> 0 | J13: =Sheet2!K10 -> 0 | ... Z13: =Sheet2!AA10 -> 0
B14: Nhiệt độ vòng bi trước | C14: =Sheet2!D11 -> 0 | D14: =Sheet2!E11 -> 0 | E14: =Sheet2!F11 -> 0 | F14: =Sheet2!G11 -> 0 | G14: =Sheet2!H11 -> 0 | H14: =Sheet2!I11 -> 0 | I14: =Sheet2!J11 -> 0 | J14: =Sheet2!K11 -> 0 | ... Z14: =Sheet2!AA11 -> 0
B15: Nhiệt độ vòng bi sau | C15: =Sheet2!D12 -> 0 | D15: =Sheet2!E12 -> 0 | E15: =Sheet2!F12 -> 0 | F15: =Sheet2!G12 -> 0 | G15: =Sheet2!H12 -> 0 | H15: =Sheet2!I12 -> 0 | I15: =Sheet2!J12 -> 0 | J15: =Sheet2!K12 -> 0 | ... Z15: =Sheet2!AA12 -> 0
B16: Dòng điện làm việc | C16: =Sheet2!D13 -> 0 | D16: =Sheet2!E13 -> 0 | E16: =Sheet2!F13 -> 0 | F16: =Sheet2!G13 -> 0 | G16: =Sheet2!H13 -> 0 | H16: =Sheet2!I13 -> 0 | I16: =Sheet2!J13 -> 0 | J16: =Sheet2!K13 -> 0 | ... Z16: =Sheet2!AA13 -> 0
B17: Độ rung dọc | C17: =Sheet2!D14 -> 0 | D17: =Sheet2!E14 -> 0 | E17: =Sheet2!F14 -> 0 | F17: =Sheet2!G14 -> 0 | G17: =Sheet2!H14 -> 0 | H17: =Sheet2!I14 -> 0 | I17: =Sheet2!J14 -> 0 | J17: =Sheet2!K14 -> 0 | ... Z17: =Sheet2!AA14 -> 0
B18: Độ rung ngang | C18: =Sheet2!D15 -> 0 | D18: =Sheet2!E15 -> 0 | E18: =Sheet2!F15 -> 0 | F18: =Sheet2!G15 -> 0 | G18: =Sheet2!H15 -> 0 | H18: =Sheet2!I15 -> 0 | I18: =Sheet2!J15 -> 0 | J18: =Sheet2!K15 -> 0 | ... Z18: =Sheet2!AA15 -> 0
A19: Máy nghiền 1B | B19: Nhiệt độ gối đỡ trước | C19: =Sheet2!D16 -> 0 | D19: =Sheet2!E16 -> 0 | E19: =Sheet2!F16 -> 0 | F19: =Sheet2!G16 -> 0 | G19: =Sheet2!H16 -> 0 | H19: =Sheet2!I16 -> 0 | I19: =Sheet2!J16 -> 0 | J19: =Sheet2!K16 -> 0 | ... Z19: =Sheet2!AA16 -> 0
B20: Nhiệt độ gối đỡ sau | C20: =Sheet2!D17 -> 0 | D20: =Sheet2!E17 -> 0 | E20: =Sheet2!F17 -> 0 | F20: =Sheet2!G17 -> 0 | G20: =Sheet2!H17 -> 0 | H20: =Sheet2!I17 -> 0 | I20: =Sheet2!J17 -> 0 | J20: =Sheet2!K17 -> 0 | ... Z20: =Sheet2!AA17 -> 0
B21: Nhiệt độ cuộn dây A | C21: =Sheet2!D18 -> 0 | D21: =Sheet2!E18 -> 0 | E21: =Sheet2!F18 -> 0 | F21: =Sheet2!G18 -> 0 | G21: =Sheet2!H18 -> 0 | H21: =Sheet2!I18 -> 0 | I21: =Sheet2!J18 -> 0 | J21: =Sheet2!K18 -> 0 | ... Z21: =Sheet2!AA18 -> 0
B22: Nhiệt độ cuộn dây B | C22: =Sheet2!D19 -> 0 | D22: =Sheet2!E19 -> 0 | E22: =Sheet2!F19 -> 0 | F22: =Sheet2!G19 -> 0 | G22: =Sheet2!H19 -> 0 | H22: =Sheet2!I19 -> 0 | I22: =Sheet2!J19 -> 0 | J22: =Sheet2!K19 -> 0 | ... Z22: =Sheet2!AA19 -> 0
B23: Nhiệt độ cuộn dây C | C23: =Sheet2!D20 -> 0 | D23: =Sheet2!E20 -> 0 | E23: =Sheet2!F20 -> 0 | F23: =Sheet2!G20 -> 0 | G23: =Sheet2!H20 -> 0 | H23: =Sheet2!I20 -> 0 | I23: =Sheet2!J20 -> 0 | J23: =Sheet2!K20 -> 0 | ... Z23: =Sheet2!AA20 -> 0
B24: Nhiệt độ vòng bi trước | C24: =Sheet2!D21 -> 0 | D24: =Sheet2!E21 -> 0 | E24: =Sheet2!F21 -> 0 | F24: =Sheet2!G21 -> 0 | G24: =Sheet2!H21 -> 0 | H24: =Sheet2!I21 -> 0 | I24: =Sheet2!J21 -> 0 | J24: =Sheet2!K21 -> 0 | ... Z24: =Sheet2!AA21 -> 0
B25: Nhiệt độ vòng bi sau | C25: =Sheet2!D22 -> 0 | D25: =Sheet2!E22 -> 0 | E25: =Sheet2!F22 -> 0 | F25: =Sheet2!G22 -> 0 | G25: =Sheet2!H22 -> 0 | H25: =Sheet2!I22 -> 0 | I25: =Sheet2!J22 -> 0 | J25: =Sheet2!K22 -> 0 | ... Z25: =Sheet2!AA22 -> 0
B26: Dòng điện làm việc | C26: =Sheet2!D23 -> 0 | D26: =Sheet2!E23 -> 0 | E26: =Sheet2!F23 -> 0 | F26: =Sheet2!G23 -> 0 | G26: =Sheet2!H23 -> 0 | H26: =Sheet2!I23 -> 0 | I26: =Sheet2!J23 -> 0 | J26: =Sheet2!K23 -> 0 | ... Z26: =Sheet2!AA23 -> 0
B27: Độ rung dọc | C27: =Sheet2!D24 -> 0 | D27: =Sheet2!E24 -> 0 | E27: =Sheet2!F24 -> 0 | F27: =Sheet2!G24 -> 0 | G27: =Sheet2!H24 -> 0 | H27: =Sheet2!I24 -> 0 | I27: =Sheet2!J24 -> 0 | J27: =Sheet2!K24 -> 0 | ... Z27: =Sheet2!AA24 -> 0
B28: Độ rung ngang | C28: =Sheet2!D25 -> 0 | D28: =Sheet2!E25 -> 0 | E28: =Sheet2!F25 -> 0 | F28: =Sheet2!G25 -> 0 | G28: =Sheet2!H25 -> 0 | H28: =Sheet2!I25 -> 0 | I28: =Sheet2!J25 -> 0 | J28: =Sheet2!K25 -> 0 | ... Z28: =Sheet2!AA25 -> 0
A29: Máy nghiền 1C | B29: Nhiệt độ gối đỡ trước | C29: =Sheet2!D26 -> 0 | D29: =Sheet2!E26 -> 0 | E29: =Sheet2!F26 -> 0 | F29: =Sheet2!G26 -> 0 | G29: =Sheet2!H26 -> 0 | H29: =Sheet2!I26 -> 0 | I29: =Sheet2!J26 -> 0 | J29: =Sheet2!K26 -> 0 | ... Z29: =Sheet2!AA26 -> 0
B30: Nhiệt độ gối đỡ sau | C30: =Sheet2!D27 -> 0 | D30: =Sheet2!E27 -> 0 | E30: =Sheet2!F27 -> 0 | F30: =Sheet2!G27 -> 0 | G30: =Sheet2!H27 -> 0 | H30: =Sheet2!I27 -> 0 | I30: =Sheet2!J27 -> 0 | J30: =Sheet2!K27 -> 0 | ... Z30: =Sheet2!AA27 -> 0
B31: Nhiệt độ cuộn dây A | C31: =Sheet2!D28 -> 0 | D31: =Sheet2!E28 -> 0 | E31: =Sheet2!F28 -> 0 | F31: =Sheet2!G28 -> 0 | G31: =Sheet2!H28 -> 0 | H31: =Sheet2!I28 -> 0 | I31: =Sheet2!J28 -> 0 | J31: =Sheet2!K28 -> 0 | ... Z31: =Sheet2!AA28 -> 0
B32: Nhiệt độ cuộn dây B | C32: =Sheet2!D29 -> 0 | D32: =Sheet2!E29 -> 0 | E32: =Sheet2!F29 -> 0 | F32: =Sheet2!G29 -> 0 | G32: =Sheet2!H29 -> 0 | H32: =Sheet2!I29 -> 0 | I32: =Sheet2!J29 -> 0 | J32: =Sheet2!K29 -> 0 | ... Z32: =Sheet2!AA29 -> 0
B33: Nhiệt độ cuộn dây C | C33: =Sheet2!D30 -> 0 | D33: =Sheet2!E30 -> 0 | E33: =Sheet2!F30 -> 0 | F33: =Sheet2!G30 -> 0 | G33: =Sheet2!H30 -> 0 | H33: =Sheet2!I30 -> 0 | I33: =Sheet2!J30 -> 0 | J33: =Sheet2!K30 -> 0 | ... Z33: =Sheet2!AA30 -> 0
B34: Nhiệt độ vòng bi trước | C34: =Sheet2!D31 -> 0 | D34: =Sheet2!E31 -> 0 | E34: =Sheet2!F31 -> 0 | F34: =Sheet2!G31 -> 0 | G34: =Sheet2!H31 -> 0 | H34: =Sheet2!I31 -> 0 | I34: =Sheet2!J31 -> 0 | J34: =Sheet2!K31 -> 0 | ... Z34: =Sheet2!AA31 -> 0
B35: Nhiệt độ vòng bi sau | C35: =Sheet2!D32 -> 0 | D35: =Sheet2!E32 -> 0 | E35: =Sheet2!F32 -> 0 | F35: =Sheet2!G32 -> 0 | G35: =Sheet2!H32 -> 0 | H35: =Sheet2!I32 -> 0 | I35: =Sheet2!J32 -> 0 | J35: =Sheet2!K32 -> 0 | ... Z35: =Sheet2!AA32 -> 0
B36: Dòng điện làm việc | C36: =Sheet2!D33 -> 0 | D36: =Sheet2!E33 -> 0 | E36: =Sheet2!F33 -> 0 | F36: =Sheet2!G33 -> 0 | G36: =Sheet2!H33 -> 0 | H36: =Sheet2!I33 -> 0 | I36: =Sheet2!J33 -> 0 | J36: =Sheet2!K33 -> 0 | ... Z36: =Sheet2!AA33 -> 0
B37: Độ rung dọc | C37: =Sheet2!D34 -> 0 | D37: =Sheet2!E34 -> 0 | E37: =Sheet2!F34 -> 0 | F37: =Sheet2!G34 -> 0 | G37: =Sheet2!H34 -> 0 | H37: =Sheet2!I34 -> 0 | I37: =Sheet2!J34 -> 0 | J37: =Sheet2!K34 -> 0 | ... Z37: =Sheet2!AA34 -> 0
B38: Độ rung ngang | C38: =Sheet2!D35 -> 0 | D38: =Sheet2!E35 -> 0 | E38: =Sheet2!F35 -> 0 | F38: =Sheet2!G35 -> 0 | G38: =Sheet2!H35 -> 0 | H38: =Sheet2!I35 -> 0 | I38: =Sheet2!J35 -> 0 | J38: =Sheet2!K35 -> 0 | ... Z38: =Sheet2!AA35 -> 0
A39: Máy nghiền 2A | B39: Nhiệt độ gối đỡ trước | C39: =Sheet2!D36 -> 0 | D39: =Sheet2!E36 -> 0 | E39: =Sheet2!F36 -> 0 | F39: =Sheet2!G36 -> 0 | G39: =Sheet2!H36 -> 0 | H39: =Sheet2!I36 -> 0 | I39: =Sheet2!J36 -> 0 | J39: =Sheet2!K36 -> 0 | ... Z39: =Sheet2!AA36 -> 0
B40: Nhiệt độ gối đỡ sau | C40: =Sheet2!D37 -> 0 | D40: =Sheet2!E37 -> 0 | E40: =Sheet2!F37 -> 0 | F40: =Sheet2!G37 -> 0 | G40: =Sheet2!H37 -> 0 | H40: =Sheet2!I37 -> 0 | I40: =Sheet2!J37 -> 0 | J40: =Sheet2!K37 -> 0 | ... Z40: =Sheet2!AA37 -> 0
B41: Nhiệt độ cuộn dây A | C41: =Sheet2!D38 -> 0 | D41: =Sheet2!E38 -> 0 | E41: =Sheet2!F38 -> 0 | F41: =Sheet2!G38 -> 0 | G41: =Sheet2!H38 -> 0 | H41: =Sheet2!I38 -> 0 | I41: =Sheet2!J38 -> 0 | J41: =Sheet2!K38 -> 0 | ... Z41: =Sheet2!AA38 -> 0
B42: Nhiệt độ cuộn dây B | C42: =Sheet2!D39 -> 0 | D42: =Sheet2!E39 -> 0 | E42: =Sheet2!F39 -> 0 | F42: =Sheet2!G39 -> 0 | G42: =Sheet2!H39 -> 0 | H42: =Sheet2!I39 -> 0 | I42: =Sheet2!J39 -> 0 | J42: =Sheet2!K39 -> 0 | ... Z42: =Sheet2!AA39 -> 0
B43: Nhiệt độ cuộn dây C | C43: =Sheet2!D40 -> 0 | D43: =Sheet2!E40 -> 0 | E43: =Sheet2!F40 -> 0 | F43: =Sheet2!G40 -> 0 | G43: =Sheet2!H40 -> 0 | H43: =Sheet2!I40 -> 0 | I43: =Sheet2!J40 -> 0 | J43: =Sheet2!K40 -> 0 | ... Z43: =Sheet2!AA40 -> 0
...

Sheet Sheet2
R1: BM.03/HD.05.62-19
E2: SỔ THEO DÕI THÔNG SỐ VẬN HÀNH ĐIỀU KHIỂN TRUNG TÂM CDQ1 | R2: Ngày hiệu lực: 10/10/2023
R4: Ngày ……tháng…..năm ….
A5: Vị trí đo/ Thời gian | C5: Kí hiệu | D5: 0.33333333 | E5: 0.375 | F5: 0.41666667 | G5: 0.45833333 | H5: 0.5 | I5: 0.54166667 | J5: 0.58333333 | K5: 0.625 | L5: 0.66666667 | M5: 0.70833333 | N5: 0.75 | O5: 0.79166667 | P5: 0.83333333 | Q5: 0.875 | R5: 0.91666667 | S5: 0.95833333 | T5: 0 | U5: 0.041666667 | V5: 0.083333333 | W5: 0.125 | X5: 0.16666667 | Y5: 0.20833333 | Z5: 0.25 | AA5: 0.29166667
A6: Máy nghiền 1A | B6: Nhiệt độ gối đỡ trước | C6: 1A_NDGOITRC
B7: Nhiệt độ gối đỡ sau | C7: 1A_NDGOISAU
B8: Nhiệt độ cuộn dây A | C8: 1A_NDCDA
B9: Nhiệt độ cuộn dây B | C9: 1A_NDCDB
B10: Nhiệt độ cuộn dây C | C10: 1A_NDCDC
B11: Nhiệt độ vòng bi trước | C11: 1A_NDVBTRC
B12: Nhiệt độ vòng bi sau | C12: 1A_NDVBSAU
B13: Dòng điện làm việc | C13: 1A_DONGDIEN
B14: Độ rung dọc | C14: 1A_RUNGDOC
B15: Độ rung ngang | C15: 1A_RUNGNGANG
A16: Máy nghiền 1B | B16: Nhiệt độ gối đỡ trước | C16: 1B_NDGOITRC
B17: Nhiệt độ gối đỡ sau | C17: 1B_NDGOISAU
B18: Nhiệt độ cuộn dây A | C18: 1B_NDCDA
B19: Nhiệt độ cuộn dây B | C19: 1B_NDCDB
B20: Nhiệt độ cuộn dây C | C20: 1B_NDCDC
B21: Nhiệt độ vòng bi trước | C21: 1B_NDVBTRC
B22: Nhiệt độ vòng bi sau | C22: 1B_NDVBSAU
B23: Dòng điện làm việc | C23: 1B_DONGDIEN
B24: Độ rung dọc | C24: 1B_RUNGDOC
B25: Độ rung ngang | C25: 1B_RUNGNGANG
A26: Máy nghiền 1C | B26: Nhiệt độ gối đỡ trước | C26: 1C_NDGOITRC | AC26: =OFFSET(Sheet2!$D$6,0,ROW(A1)-1) -> 0
B27: Nhiệt độ gối đỡ sau | C27: 1C_NDGOISAU
B28: Nhiệt độ cuộn dây A | C28: 1C_NDCDA
B29: Nhiệt độ cuộn dây B | C29: 1C_NDCDB
B30: Nhiệt độ cuộn dây C | C30: 1C_NDCDC
B31: Nhiệt độ vòng bi trước | C31: 1C_NDVBTRC
B32: Nhiệt độ vòng bi sau | C32: 1C_NDVBSAU
B33: Dòng điện làm việc | C33: 1C_DONGDIEN
B34: Độ rung dọc | C34: 1C_RUNGDOC
B35: Độ rung ngang | C35: 1C_RUNGNGANG
A36: Máy nghiền 2A | B36: Nhiệt độ gối đỡ trước | C36: 2A_NDGOITRC
B37: Nhiệt độ gối đỡ sau | C37: 2A_NDGOISAU
B38: Nhiệt độ cuộn dây A | C38: 2A_NDCDA
B39: Nhiệt độ cuộn dây B | C39: 2A_NDCDB
B40: Nhiệt độ cuộn dây C | C40: 2A_NDCDC
B41: Nhiệt độ vòng bi trước | C41: 2A_NDVBTRC
...
