Workbook

Sheet Sheet1
AB1: BM.04/QT.05.04
AB2: Ngày hiệu lực: 01/01/2024
F4: NHẬT KÝ VẬN HÀNH LÒ VÔI ĐỨNG SỐ 3
A6: Mục | B6: Vị trí đo Thời gian | F6: 8:00 | G6: 9:00 | H6: 10:00 | I6: 11:00 | J6: 12:00 | K6: 13:00 | L6: 14:00 | M6: 15:00 | N6: 16:00 | O6: 17:00 | P6: 18:00 | Q6: 19:00 | R6: 20:00 | S6: 21:00 | T6: 22:00 | U6: 23:00 | V6: 0:00 | W6: 1:00 | X6: 2:00 | Y6: 3:00 | Z6: 4:00 | AA6: 5:00 | AB6: 6:00 | AC6: 7:00
A7: Nhiệt độ (℃) | B7: Khí thải đỉnh lò | E7: 5404 | F7: =Sheet2!E6 -> 0 | G7: =Sheet2!F6 -> 0 | H7: =Sheet2!G6 -> 0 | I7: =Sheet2!H6 -> 0 | J7: =Sheet2!I6 -> 0 | K7: =Sheet2!J6 -> 0 | L7: =Sheet2!K6 -> 0 | M7: =Sheet2!L6 -> 0 | ... AC7: =Sheet2!AB6 -> 0
E8: 5408 | F8: =Sheet2!E7 -> 0 | G8: =Sheet2!F7 -> 0 | H8: =Sheet2!G7 -> 0 | I8: =Sheet2!H7 -> 0 | J8: =Sheet2!I7 -> 0 | K8: =Sheet2!J7 -> 0 | L8: =Sheet2!K7 -> 0 | M8: =Sheet2!L7 -> 0 | ... AC8: =Sheet2!AB7 -> 0
E9: 5414 | F9: =Sheet2!E8 -> 0 | G9: =Sheet2!F8 -> 0 | H9: =Sheet2!G8 -> 0 | I9: =Sheet2!H8 -> 0 | J9: =Sheet2!I8 -> 0 | K9: =Sheet2!J8 -> 0 | L9: =Sheet2!K8 -> 0 | M9: =Sheet2!L8 -> 0 | ... AC9: =Sheet2!AB8 -> 0
E10: 5418 | F10: =Sheet2!E9 -> 0 | G10: =Sheet2!F9 -> 0 | H10: =Sheet2!G9 -> 0 | I10: =Sheet2!H9 -> 0 | J10: =Sheet2!I9 -> 0 | K10: =Sheet2!J9 -> 0 | L10: =Sheet2!K9 -> 0 | M10: =Sheet2!L9 -> 0 | ... AC10: =Sheet2!AB9 -> 0
B11: Vùng dự nhiệt | E11: 4405 | F11: =Sheet2!E10 -> 0 | G11: =Sheet2!F10 -> 0 | H11: =Sheet2!G10 -> 0 | I11: =Sheet2!H10 -> 0 | J11: =Sheet2!I10 -> 0 | K11: =Sheet2!J10 -> 0 | L11: =Sheet2!K10 -> 0 | M11: =Sheet2!L10 -> 0 | ... AC11: =Sheet2!AB10 -> 0
E12: 4412 | F12: =Sheet2!E11 -> 0 | G12: =Sheet2!F11 -> 0 | H12: =Sheet2!G11 -> 0 | I12: =Sheet2!H11 -> 0 | J12: =Sheet2!I11 -> 0 | K12: =Sheet2!J11 -> 0 | L12: =Sheet2!K11 -> 0 | M12: =Sheet2!L11 -> 0 | ... AC12: =Sheet2!AB11 -> 0
E13: 4420 | F13: =Sheet2!E12 -> 0 | G13: =Sheet2!F12 -> 0 | H13: =Sheet2!G12 -> 0 | I13: =Sheet2!H12 -> 0 | J13: =Sheet2!I12 -> 0 | K13: =Sheet2!J12 -> 0 | L13: =Sheet2!K12 -> 0 | M13: =Sheet2!L12 -> 0 | ... AC13: =Sheet2!AB12 -> 0
B14: Biên vùng dự nhiệt | E14: 4402 | F14: =Sheet2!E13 -> 0 | G14: =Sheet2!F13 -> 0 | H14: =Sheet2!G13 -> 0 | I14: =Sheet2!H13 -> 0 | J14: =Sheet2!I13 -> 0 | K14: =Sheet2!J13 -> 0 | L14: =Sheet2!K13 -> 0 | M14: =Sheet2!L13 -> 0 | ... AC14: =Sheet2!AB13 -> 0
E15: 4405 | F15: =Sheet2!E14 -> 0 | G15: =Sheet2!F14 -> 0 | H15: =Sheet2!G14 -> 0 | I15: =Sheet2!H14 -> 0 | J15: =Sheet2!I14 -> 0 | K15: =Sheet2!J14 -> 0 | L15: =Sheet2!K14 -> 0 | M15: =Sheet2!L14 -> 0 | ... AC15: =Sheet2!AB14 -> 0
E16: 4409 | F16: =Sheet2!E15 -> 0 | G16: =Sheet2!F15 -> 0 | H16: =Sheet2!G15 -> 0 | I16: =Sheet2!H15 -> 0 | J16: =Sheet2!I15 -> 0 | K16: =Sheet2!J15 -> 0 | L16: =Sheet2!K15 -> 0 | M16: =Sheet2!L15 -> 0 | ... AC16: =Sheet2!AB15 -> 0
E17: 4412 | F17: =Sheet2!E16 -> 0 | G17: =Sheet2!F16 -> 0 | H17: =Sheet2!G16 -> 0 | I17: =Sheet2!H16 -> 0 | J17: =Sheet2!I16 -> 0 | K17: =Sheet2!J16 -> 0 | L17: =Sheet2!K16 -> 0 | M17: =Sheet2!L16 -> 0 | ... AC17: =Sheet2!AB16 -> 0
E18: 4415 | F18: =Sheet2!E17 -> 0 | G18: =Sheet2!F17 -> 0 | H18: =Sheet2!G17 -> 0 | I18: =Sheet2!H17 -> 0 | J18: =Sheet2!I17 -> 0 | K18: =Sheet2!J17 -> 0 | L18: =Sheet2!K17 -> 0 | M18: =Sheet2!L17 -> 0 | ... AC18: =Sheet2!AB17 -> 0
E19: 4419 | F19: =Sheet2!E18 -> 0 | G19: =Sheet2!F18 -> 0 | H19: =Sheet2!G18 -> 0 | I19: =Sheet2!H18 -> 0 | J19: =Sheet2!I18 -> 0 | K19: =Sheet2!J18 -> 0 | L19: =Sheet2!K18 -> 0 | M19: =Sheet2!L18 -> 0 | ... AC19: =Sheet2!AB18 -> 0
B20: Vùng nung | E20: 3201 | F20: =Sheet2!E19 -> 0 | G20: =Sheet2!F19 -> 0 | H20: =Sheet2!G19 -> 0 | I20: =Sheet2!H19 -> 0 | J20: =Sheet2!I19 -> 0 | K20: =Sheet2!J19 -> 0 | L20: =Sheet2!K19 -> 0 | M20: =Sheet2!L19 -> 0 | ... AC20: =Sheet2!AB19 -> 0
E21: 3203 | F21: =Sheet2!E20 -> 0 | G21: =Sheet2!F20 -> 0 | H21: =Sheet2!G20 -> 0 | I21: =Sheet2!H20 -> 0 | J21: =Sheet2!I20 -> 0 | K21: =Sheet2!J20 -> 0 | L21: =Sheet2!K20 -> 0 | M21: =Sheet2!L20 -> 0 | ... AC21: =Sheet2!AB20 -> 0
E22: 3206 | F22: =Sheet2!E21 -> 0 | G22: =Sheet2!F21 -> 0 | H22: =Sheet2!G21 -> 0 | I22: =Sheet2!H21 -> 0 | J22: =Sheet2!I21 -> 0 | K22: =Sheet2!J21 -> 0 | L22: =Sheet2!K21 -> 0 | M22: =Sheet2!L21 -> 0 | ... AC22: =Sheet2!AB21 -> 0
E23: 3208 | F23: =Sheet2!E22 -> 0 | G23: =Sheet2!F22 -> 0 | H23: =Sheet2!G22 -> 0 | I23: =Sheet2!H22 -> 0 | J23: =Sheet2!I22 -> 0 | K23: =Sheet2!J22 -> 0 | L23: =Sheet2!K22 -> 0 | M23: =Sheet2!L22 -> 0 | ... AC23: =Sheet2!AB22 -> 0
E24: 3211 | F24: =Sheet2!E23 -> 0 | G24: =Sheet2!F23 -> 0 | H24: =Sheet2!G23 -> 0 | I24: =Sheet2!H23 -> 0 | J24: =Sheet2!I23 -> 0 | K24: =Sheet2!J23 -> 0 | L24: =Sheet2!K23 -> 0 | M24: =Sheet2!L23 -> 0 | ... AC24: =Sheet2!AB23 -> 0
E25: 3213 | F25: =Sheet2!E24 -> 0 | G25: =Sheet2!F24 -> 0 | H25: =Sheet2!G24 -> 0 | I25: =Sheet2!H24 -> 0 | J25: =Sheet2!I24 -> 0 | K25: =Sheet2!J24 -> 0 | L25: =Sheet2!K24 -> 0 | M25: =Sheet2!L24 -> 0 | ... AC25: =Sheet2!AB24 -> 0
E26: 3216 | F26: =Sheet2!E25 -> 0 | G26: =Sheet2!F25 -> 0 | H26: =Sheet2!G25 -> 0 | I26: =Sheet2!H25 -> 0 | J26: =Sheet2!I25 -> 0 | K26: =Sheet2!J25 -> 0 | L26: =Sheet2!K25 -> 0 | M26: =Sheet2!L25 -> 0 | ... AC26: =Sheet2!AB25 -> 0
E27: 3218 | F27: =Sheet2!E26 -> 0 | G27: =Sheet2!F26 -> 0 | H27: =Sheet2!G26 -> 0 | I27: =Sheet2!H26 -> 0 | J27: =Sheet2!I26 -> 0 | K27: =Sheet2!J26 -> 0 | L27: =Sheet2!K26 -> 0 | M27: =Sheet2!L26 -> 0 | ... AC27: =Sheet2!AB26 -> 0
B28: Vùng làm mát đáy lò | E28: 1808 | F28: =Sheet2!E27 -> 0 | G28: =Sheet2!F27 -> 0 | H28: =Sheet2!G27 -> 0 | I28: =Sheet2!H27 -> 0 | J28: =Sheet2!I27 -> 0 | K28: =Sheet2!J27 -> 0 | L28: =Sheet2!K27 -> 0 | M28: =Sheet2!L27 -> 0 | ... AC28: =Sheet2!AB27 -> 0
E29: 1818 | F29: =Sheet2!E28 -> 0 | G29: =Sheet2!F28 -> 0 | H29: =Sheet2!G28 -> 0 | I29: =Sheet2!H28 -> 0 | J29: =Sheet2!I28 -> 0 | K29: =Sheet2!J28 -> 0 | L29: =Sheet2!K28 -> 0 | M29: =Sheet2!L28 -> 0 | ... AC29: =Sheet2!AB28 -> 0
B30: Xả liệu đáy lò | E30: 1403 | F30: =Sheet2!E29 -> 0 | G30: =Sheet2!F29 -> 0 | H30: =Sheet2!G29 -> 0 | I30: =Sheet2!H29 -> 0 | J30: =Sheet2!I29 -> 0 | K30: =Sheet2!J29 -> 0 | L30: =Sheet2!K29 -> 0 | M30: =Sheet2!L29 -> 0 | ... AC30: =Sheet2!AB29 -> 0
E31: 1408 | F31: =Sheet2!E30 -> 0 | G31: =Sheet2!F30 -> 0 | H31: =Sheet2!G30 -> 0 | I31: =Sheet2!H30 -> 0 | J31: =Sheet2!I30 -> 0 | K31: =Sheet2!J30 -> 0 | L31: =Sheet2!K30 -> 0 | M31: =Sheet2!L30 -> 0 | ... AC31: =Sheet2!AB30 -> 0
E32: 1413 | F32: =Sheet2!E31 -> 0 | G32: =Sheet2!F31 -> 0 | H32: =Sheet2!G31 -> 0 | I32: =Sheet2!H31 -> 0 | J32: =Sheet2!I31 -> 0 | K32: =Sheet2!J31 -> 0 | L32: =Sheet2!K31 -> 0 | M32: =Sheet2!L31 -> 0 | ... AC32: =Sheet2!AB31 -> 0
E33: 1418 | F33: =Sheet2!E32 -> 0 | G33: =Sheet2!F32 -> 0 | H33: =Sheet2!G32 -> 0 | I33: =Sheet2!H32 -> 0 | J33: =Sheet2!I32 -> 0 | K33: =Sheet2!J32 -> 0 | L33: =Sheet2!K32 -> 0 | M33: =Sheet2!L32 -> 0 | ... AC33: =Sheet2!AB32 -> 0
B34: Ống vây gió trợ đốt | E34: 4311 | F34: =Sheet2!E33 -> 0 | G34: =Sheet2!F33 -> 0 | H34: =Sheet2!G33 -> 0 | I34: =Sheet2!H33 -> 0 | J34: =Sheet2!I33 -> 0 | K34: =Sheet2!J33 -> 0 | L34: =Sheet2!K33 -> 0 | M34: =Sheet2!L33 -> 0 | ... AC34: =Sheet2!AB33 -> 0
B35: Bộ trao dổi nhiệt | D35: Khí thải đầu vào | F35: =Sheet2!E34 -> 0 | G35: =Sheet2!F34 -> 0 | H35: =Sheet2!G34 -> 0 | I35: =Sheet2!H34 -> 0 | J35: =Sheet2!I34 -> 0 | K35: =Sheet2!J34 -> 0 | L35: =Sheet2!K34 -> 0 | M35: =Sheet2!L34 -> 0 | ... AC35: =Sheet2!AB34 -> 0
D36: Khí than đầu vào | F36: =Sheet2!E35 -> 0 | G36: =Sheet2!F35 -> 0 | H36: =Sheet2!G35 -> 0 | I36: =Sheet2!H35 -> 0 | J36: =Sheet2!I35 -> 0 | K36: =Sheet2!J35 -> 0 | L36: =Sheet2!K35 -> 0 | M36: =Sheet2!L35 -> 0 | ... AC36: =Sheet2!AB35 -> 0
D37: Khí than đầu ra | F37: =Sheet2!E36 -> 0 | G37: =Sheet2!F36 -> 0 | H37: =Sheet2!G36 -> 0 | I37: =Sheet2!H36 -> 0 | J37: =Sheet2!I36 -> 0 | K37: =Sheet2!J36 -> 0 | L37: =Sheet2!K36 -> 0 | M37: =Sheet2!L36 -> 0 | ... AC37: =Sheet2!AB36 -> 0
B38: Làm mát dầm gió đầu ra | F38: =Sheet2!E37 -> 0 | G38: =Sheet2!F37 -> 0 | H38: =Sheet2!G37 -> 0 | I38: =Sheet2!H37 -> 0 | J38: =Sheet2!I37 -> 0 | K38: =Sheet2!J37 -> 0 | L38: =Sheet2!K37 -> 0 | M38: =Sheet2!L37 -> 0 | ... AC38: =Sheet2!AB37 -> 0
B39: Bộ lọc bụi | D39: Đầu vào | E39: TE-01 | F39: =Sheet2!E38 -> 0 | G39: =Sheet2!F38 -> 0 | H39: =Sheet2!G38 -> 0 | I39: =Sheet2!H38 -> 0 | J39: =Sheet2!I38 -> 0 | K39: =Sheet2!J38 -> 0 | L39: =Sheet2!K38 -> 0 | M39: =Sheet2!L38 -> 0 | ... AC39: =Sheet2!AB38 -> 0
D40: Đầu ra | E40: TE-02 | F40: =Sheet2!E39 -> 0 | G40: =Sheet2!F39 -> 0 | H40: =Sheet2!G39 -> 0 | I40: =Sheet2!H39 -> 0 | J40: =Sheet2!I39 -> 0 | K40: =Sheet2!J39 -> 0 | L40: =Sheet2!K39 -> 0 | M40: =Sheet2!L39 -> 0 | ... AC40: =Sheet2!AB39 -> 0
A41: Áp suất (Kpa) | B41: Ống tổng khí than | E41: PT01 | F41: =Sheet2!E40 -> 0 | G41: =Sheet2!F40 -> 0 | H41: =Sheet2!G40 -> 0 | I41: =Sheet2!H40 -> 0 | J41: =Sheet2!I40 -> 0 | K41: =Sheet2!J40 -> 0 | L41: =Sheet2!K40 -> 0 | M41: =Sheet2!L40 -> 0 | ... AC41: =Sheet2!AB40 -> 0
B42: Ống vây khí than hàng 1 | E42: PT02 | F42: =Sheet2!E41 -> 0 | G42: =Sheet2!F41 -> 0 | H42: =Sheet2!G41 -> 0 | I42: =Sheet2!H41 -> 0 | J42: =Sheet2!I41 -> 0 | K42: =Sheet2!J41 -> 0 | L42: =Sheet2!K41 -> 0 | M42: =Sheet2!L41 -> 0 | ... AC42: =Sheet2!AB41 -> 0
...

Sheet Sheet2
Q1: BM.03/HD.05.62-19
D2: NHẬT KÝ VẬN HÀNH LÒ VÔI ĐỨNG SỐ 1 | Q2: Ngày hiệu lực: 10/10/2023
Q4: Ngày ……tháng…..năm ….
A5: Vị trí đo/ Thời gian | D5: Kí hiệu | E5: 0.33333333 | F5: 0.375 | G5: 0.41666667 | H5: 0.45833333 | I5: 0.5 | J5: 0.54166667 | K5: 0.58333333 | L5: 0.625 | M5: 0.66666667 | N5: 0.70833333 | O5: 0.75 | P5: 0.79166667 | Q5: 0.83333333 | R5: 0.875 | S5: 0.91666667 | T5: 0.95833333 | U5: 0 | V5: 0.041666667 | W5: 0.083333333 | X5: 0.125 | Y5: 0.16666667 | Z5: 0.20833333 | AA5: 0.25 | AB5: 0.29166667
A6: Nhiệt độ | B6: Khí thải đỉnh lò | C6: 5404 | D6: 3#_Kiln_4#_Exhaust_gas_temperature
C7: 5408 | D7: 3#_Kiln_8#_Exhaust_gas_temperature
C8: 5414 | D8: 3#_Kiln_14#_Exhaust_gas_temperature
C9: 5418 | D9: 3#_Kiln_18#_Exhaust_gas_temperature
B10: Vùng dự nhiệt | C10: 4405 | D10: 3#_Kiln_5#_matter_ring_temperature
C11: 4412 | D11: 3#_Kiln_12#_Noodle_ring_temperature
C12: 4420 | D12: 3#_Kiln_20#_Noodle_ring_temperature
B13: Biên vùng dự nhiệt | C13: 4402 | D13: 3#_Kiln_2#_Matter_edge_temperature
C14: 4405 | D14: 3#_Kiln_5#_Matter_edge_temperature
C15: 4409 | D15: 3#_Kiln_9#_Matter_edge_temperature
C16: 4412 | D16: 3#_Kiln_12#_Matter_edge_temperature
C17: 4415 | D17: 3#_Kiln_15#_Matter_edge_temperature
C18: 4419 | D18: 3#_Kiln_19#_Matter_edge_temperature
B19: Vùng nung | C19: 3201 | D19: 3#_Kiln_1#_Roasting_belt_temperature
C20: 3203 | D20: 3#_Kiln_3#_Roasting_belt_temperature
C21: 3206 | D21: 3#_Kiln_6#_Roasting_belt_temperature
C22: 3208 | D22: 3#_Kiln_8#_Roasting_belt_temperature
C23: 3211 | D23: 3#_Kiln_11#_Roasting_belt_temperature
C24: 3213 | D24: 3#_Kiln_13#_Roasting_belt_temperature
C25: 3216 | D25: 3#_Kiln_16#_Roasting_belt_temperature
C26: 3218 | D26: 3#_Kiln_18#_Roasting_belt_temperature
B27: Vùng làm mát đáy lò | C27: 1808 | D27: 3#_Kiln_8#_cooling_zone_temperature
C28: 1818 | D28: 3#_Kiln_18#_cooling_zone_temperature
B29: Xả liệu đáy lò | C29: 1403 | D29: 3#_Kiln_bottom_discharge_3#_temperature
C30: 1408 | D30: 3#_Kiln_bottom_discharge_8#_temperature
C31: 1413 | D31: 3#_Kiln_bottom_discharge_13#_temperature
C32: 1418 | D32: 3#_Kiln_bottom_discharge_18#_temperature
B33: Ống vây gió trợ đốt | C33: 4311 | D33: 3#_Kiln_hot_combustion_air_total_pipe_temperature
B34: Bộ trao dổi nhiệt | C34: Khí thải đầu vào | D34: 3#_Kiln_Gas_heat_exchanger_Exhaust_gas_import_temperature
C35: Khí than đầu vào | D35: 3#_Kiln_Gas_heat_exchanger_gas_import_temperature
C36: Khí than đầu ra | D36: 3#_Kiln_Gas_heat_exchanger_gas_export_temperature
B37: Làm mát dầm gió đầu ra | D37: 3#_Kiln_Air_cooled_beam_outlet_temperature
B38: Bộ lọc bụi | C38: Đầu vào | D38: 3#_Kiln_Top_filter_inlet_temperature
C39: Đầu ra | D39: 3#_Kiln_Top_filter_outlet_temperature
A40: Áp suất (Kpa) | B40: Ống tổng khí than | D40: 3#_Kiln_gas_main_pipe_pressure
B41: Ống vây khí than hàng 1 | D41: 3#_Kiln_NO_1_gas_surrounding_pipe_pressure
...

Sheet Ca Ngay
V1: BM.04/QT.05.04
V2: Ngày hiệu lực: 01/01/2024
F4: NHẬT KÝ VẬN HÀNH LÒ VÔI ĐỨNG SỐ 3
A6: Mục | B6: Vị trí đo Thời gian | F6: 8:00 (20:00) | G6: 10:00 (22:00) | H6: 12:00 (0:00) | I6: 14:00 (2:00) | J6: 16:00 (4:00) | K6: 18:00 (6:00) | L6: Mục | M6: Vị trí đo Thời gian | Q6: 8:00 (20:00) | R6: 10:00 (22:00) | S6: 12:00 (0:00) | T6: 14:00 (2:00) | U6: 16:00 (4:00) | V6: 18:00 (6:00)
A7: Nhiệt độ (℃) | B7: Khí thải đỉnh lò | E7: 5404 | F7: =Sheet1!F7 -> 0 | G7: =Sheet1!H7 -> 0 | H7: =Sheet1!J7 -> 0 | I7: =Sheet1!L7 -> 0 | J7: =Sheet1!N7 -> 0 | K7: =Sheet1!P7 -> 0 | L7: Áp suất (Kpa) | M7: Ống tổng khí than | P7: PT01 | Q7: =Sheet1!F41 -> 0 | R7: =Sheet1!H41 -> 0 | S7: =Sheet1!J41 -> 0 | T7: =Sheet1!L41 -> 0 | U7: =Sheet1!N41 -> 0 | V7: =Sheet1!P41 -> 0
E8: 5408 | F8: =Sheet1!F8 -> 0 | G8: =Sheet1!H8 -> 0 | H8: =Sheet1!J8 -> 0 | I8: =Sheet1!L8 -> 0 | J8: =Sheet1!N8 -> 0 | K8: =Sheet1!P8 -> 0 | M8: Ống vây khí than hàng 1 | P8: PT02 | Q8: =Sheet1!F42 -> 0 | R8: =Sheet1!H42 -> 0 | S8: =Sheet1!J42 -> 0 | T8: =Sheet1!L42 -> 0 | U8: =Sheet1!N42 -> 0 | V8: =Sheet1!P42 -> 0
E9: 5414 | F9: =Sheet1!F9 -> 0 | G9: =Sheet1!H9 -> 0 | H9: =Sheet1!J9 -> 0 | I9: =Sheet1!L9 -> 0 | J9: =Sheet1!N9 -> 0 | K9: =Sheet1!P9 -> 0 | M9: Ống vây khí than hàng 2 | P9: PT03 | Q9: =Sheet1!F43 -> 0 | R9: =Sheet1!H43 -> 0 | S9: =Sheet1!J43 -> 0 | T9: =Sheet1!L43 -> 0 | U9: =Sheet1!N43 -> 0 | V9: =Sheet1!P43 -> 0
E10: 5418 | F10: =Sheet1!F10 -> 0 | G10: =Sheet1!H10 -> 0 | H10: =Sheet1!J10 -> 0 | I10: =Sheet1!L10 -> 0 | J10: =Sheet1!N10 -> 0 | K10: =Sheet1!P10 -> 0 | M10: Ống vây khí than hàng 3 | P10: PT04 | Q10: =Sheet1!F44 -> 0 | R10: =Sheet1!H44 -> 0 | S10: =Sheet1!J44 -> 0 | T10: =Sheet1!L44 -> 0 | U10: =Sheet1!N44 -> 0 | V10: =Sheet1!P44 -> 0
B11: Vùng dự nhiệt | E11: 4405 | F11: =Sheet1!F11 -> 0 | G11: =Sheet1!H11 -> 0 | H11: =Sheet1!J11 -> 0 | I11: =Sheet1!L11 -> 0 | J11: =Sheet1!N11 -> 0 | K11: =Sheet1!P11 -> 0 | M11: Ống vây khí than hàng 4 | P11: PT05 | Q11: =Sheet1!F45 -> 0 | R11: =Sheet1!H45 -> 0 | S11: =Sheet1!J45 -> 0 | T11: =Sheet1!L45 -> 0 | U11: =Sheet1!N45 -> 0 | V11: =Sheet1!P45 -> 0
E12: 4412 | F12: =Sheet1!F12 -> 0 | G12: =Sheet1!H12 -> 0 | H12: =Sheet1!J12 -> 0 | I12: =Sheet1!L12 -> 0 | J12: =Sheet1!N12 -> 0 | K12: =Sheet1!P12 -> 0 | M12: Ống vây khí than trung tâm | P12: PT06 | Q12: =Sheet1!F46 -> 0 | R12: =Sheet1!H46 -> 0 | S12: =Sheet1!J46 -> 0 | T12: =Sheet1!L46 -> 0 | U12: =Sheet1!N46 -> 0 | V12: =Sheet1!P46 -> 0
E13: 4420 | F13: =Sheet1!F13 -> 0 | G13: =Sheet1!H13 -> 0 | H13: =Sheet1!J13 -> 0 | I13: =Sheet1!L13 -> 0 | J13: =Sheet1!N13 -> 0 | K13: =Sheet1!P13 -> 0 | M13: Ống vây gió trợ đốt hàng 1 | P13: PT07 | Q13: =Sheet1!F47 -> 0 | R13: =Sheet1!H47 -> 0 | S13: =Sheet1!J47 -> 0 | T13: =Sheet1!L47 -> 0 | U13: =Sheet1!N47 -> 0 | V13: =Sheet1!P47 -> 0
B14: Biên vùng dự nhiệt | E14: 4402 | F14: =Sheet1!F14 -> 0 | G14: =Sheet1!H14 -> 0 | H14: =Sheet1!J14 -> 0 | I14: =Sheet1!L14 -> 0 | J14: =Sheet1!N14 -> 0 | K14: =Sheet1!P14 -> 0 | M14: Ống vây gió trợ đốt hàng 2 | P14: PT08 | Q14: =Sheet1!F48 -> 0 | R14: =Sheet1!H48 -> 0 | S14: =Sheet1!J48 -> 0 | T14: =Sheet1!L48 -> 0 | U14: =Sheet1!N48 -> 0 | V14: =Sheet1!P48 -> 0
E15: 4405 | F15: =Sheet1!F15 -> 0 | G15: =Sheet1!H15 -> 0 | H15: =Sheet1!J15 -> 0 | I15: =Sheet1!L15 -> 0 | J15: =Sheet1!N15 -> 0 | K15: =Sheet1!P15 -> 0 | M15: Ống vây gió trợ đốt hàng 3 | P15: PT09 | Q15: =Sheet1!F49 -> 0 | R15: =Sheet1!H49 -> 0 | S15: =Sheet1!J49 -> 0 | T15: =Sheet1!L49 -> 0 | U15: =Sheet1!N49 -> 0 | V15: =Sheet1!P49 -> 0
E16: 4409 | F16: =Sheet1!F16 -> 0 | G16: =Sheet1!H16 -> 0 | H16: =Sheet1!J16 -> 0 | I16: =Sheet1!L16 -> 0 | J16: =Sheet1!N16 -> 0 | K16: =Sheet1!P16 -> 0 | M16: Ống vây gió trợ đốt hàng 4 | P16: PT10 | Q16: =Sheet1!F50 -> 0 | R16: =Sheet1!H50 -> 0 | S16: =Sheet1!J50 -> 0 | T16: =Sheet1!L50 -> 0 | U16: =Sheet1!N50 -> 0 | V16: =Sheet1!P50 -> 0
E17: 4412 | F17: =Sheet1!F17 -> 0 | G17: =Sheet1!H17 -> 0 | H17: =Sheet1!J17 -> 0 | I17: =Sheet1!L17 -> 0 | J17: =Sheet1!N17 -> 0 | K17: =Sheet1!P17 -> 0 | M17: Ống vây gió trợ đốt trung tâm | P17: PT11 | Q17: =Sheet1!F51 -> 0 | R17: =Sheet1!H51 -> 0 | S17: =Sheet1!J51 -> 0 | T17: =Sheet1!L51 -> 0 | U17: =Sheet1!N51 -> 0 | V17: =Sheet1!P51 -> 0
E18: 4415 | F18: =Sheet1!F18 -> 0 | G18: =Sheet1!H18 -> 0 | H18: =Sheet1!J18 -> 0 | I18: =Sheet1!L18 -> 0 | J18: =Sheet1!N18 -> 0 | K18: =Sheet1!P18 -> 0 | M18: Áp suất trong lò | P18: PT15 | Q18: =Sheet1!F52 -> 0 | R18: =Sheet1!H52 -> 0 | S18: =Sheet1!J52 -> 0 | T18: =Sheet1!L52 -> 0 | U18: =Sheet1!N52 -> 0 | V18: =Sheet1!P52 -> 0
E19: 4419 | F19: =Sheet1!F19 -> 0 | G19: =Sheet1!H19 -> 0 | H19: =Sheet1!J19 -> 0 | I19: =Sheet1!L19 -> 0 | J19: =Sheet1!N19 -> 0 | K19: =Sheet1!P19 -> 0 | M19: Ống vây gió điều tiết nhiệt | P19: PT12 | Q19: =Sheet1!F53 -> 0 | R19: =Sheet1!H53 -> 0 | S19: =Sheet1!J53 -> 0 | T19: =Sheet1!L53 -> 0 | U19: =Sheet1!N53 -> 0 | V19: =Sheet1!P53 -> 0
B20: Vùng nung | E20: 3201 | F20: =Sheet1!F20 -> 0 | G20: =Sheet1!H20 -> 0 | H20: =Sheet1!J20 -> 0 | I20: =Sheet1!L20 -> 0 | J20: =Sheet1!N20 -> 0 | K20: =Sheet1!P20 -> 0 | M20: Gió làm mát đáy lò | P20: PT13 | Q20: =Sheet1!F54 -> 0 | R20: =Sheet1!H54 -> 0 | S20: =Sheet1!J54 -> 0 | T20: =Sheet1!L54 -> 0 | U20: =Sheet1!N54 -> 0 | V20: =Sheet1!P54 -> 0
E21: 3203 | F21: =Sheet1!F21 -> 0 | G21: =Sheet1!H21 -> 0 | H21: =Sheet1!J21 -> 0 | I21: =Sheet1!L21 -> 0 | J21: =Sheet1!N21 -> 0 | K21: =Sheet1!P21 -> 0 | M21: Ống vây gió làm mát | P21: PT14 | Q21: =Sheet1!F55 -> 0 | R21: =Sheet1!H55 -> 0 | S21: =Sheet1!J55 -> 0 | T21: =Sheet1!L55 -> 0 | U21: =Sheet1!N55 -> 0 | V21: =Sheet1!P55 -> 0
E22: 3206 | F22: =Sheet1!F22 -> 0 | G22: =Sheet1!H22 -> 0 | H22: =Sheet1!J22 -> 0 | I22: =Sheet1!L22 -> 0 | J22: =Sheet1!N22 -> 0 | K22: =Sheet1!P22 -> 0 | M22: Áp suất quạt trợ đốt | P22: PT17 | Q22: =Sheet1!F56 -> 0 | R22: =Sheet1!H56 -> 0 | S22: =Sheet1!J56 -> 0 | T22: =Sheet1!L56 -> 0 | U22: =Sheet1!N56 -> 0 | V22: =Sheet1!P56 -> 0
E23: 3208 | F23: =Sheet1!F23 -> 0 | G23: =Sheet1!H23 -> 0 | H23: =Sheet1!J23 -> 0 | I23: =Sheet1!L23 -> 0 | J23: =Sheet1!N23 -> 0 | K23: =Sheet1!P23 -> 0 | M23: Áp suất quạt làm mát | P23: PT18 | Q23: =Sheet1!F57 -> 0 | R23: =Sheet1!H57 -> 0 | S23: =Sheet1!J57 -> 0 | T23: =Sheet1!L57 -> 0 | U23: =Sheet1!N57 -> 0 | V23: =Sheet1!P57 -> 0
E24: 3211 | F24: =Sheet1!F24 -> 0 | G24: =Sheet1!H24 -> 0 | H24: =Sheet1!J24 -> 0 | I24: =Sheet1!L24 -> 0 | J24: =Sheet1!N24 -> 0 | K24: =Sheet1!P24 -> 0 | M24: Áp đỉnh lò | P24: PT016 | Q24: =Sheet1!F58 -> 0 | R24: =Sheet1!H58 -> 0 | S24: =Sheet1!J58 -> 0 | T24: =Sheet1!L58 -> 0 | U24: =Sheet1!N58 -> 0 | V24: =Sheet1!P58 -> 0
E25: 3213 | F25: =Sheet1!F25 -> 0 | G25: =Sheet1!H25 -> 0 | H25: =Sheet1!J25 -> 0 | I25: =Sheet1!L25 -> 0 | J25: =Sheet1!N25 -> 0 | K25: =Sheet1!P25 -> 0 | M25: Khí Ni tơ | P25: PT019 | Q25: =Sheet1!F59 -> 0 | R25: =Sheet1!H59 -> 0 | S25: =Sheet1!J59 -> 0 | T25: =Sheet1!L59 -> 0 | U25: =Sheet1!N59 -> 0 | V25: =Sheet1!P59 -> 0
E26: 3216 | F26: =Sheet1!F26 -> 0 | G26: =Sheet1!H26 -> 0 | H26: =Sheet1!J26 -> 0 | I26: =Sheet1!L26 -> 0 | J26: =Sheet1!N26 -> 0 | K26: =Sheet1!P26 -> 0 | L26: Lưu lượng (m3/h) | M26: Ống khí than trung tâm | P26: FT01 | Q26: =Sheet1!F60 -> 0 | R26: =Sheet1!H60 -> 0 | S26: =Sheet1!J60 -> 0 | T26: =Sheet1!L60 -> 0 | U26: =Sheet1!N60 -> 0 | V26: =Sheet1!P60 -> 0
E27: 3218 | F27: =Sheet1!F27 -> 0 | G27: =Sheet1!H27 -> 0 | H27: =Sheet1!J27 -> 0 | I27: =Sheet1!L27 -> 0 | J27: =Sheet1!N27 -> 0 | K27: =Sheet1!P27 -> 0 | M27: Ống vây khí than sườn hàng 1 | P27: FT02 | Q27: =Sheet1!F61 -> 0 | R27: =Sheet1!H61 -> 0 | S27: =Sheet1!J61 -> 0 | T27: =Sheet1!L61 -> 0 | U27: =Sheet1!N61 -> 0 | V27: =Sheet1!P61 -> 0
B28: Vùng làm mát đáy lò | E28: 1808 | F28: =Sheet1!F28 -> 0 | G28: =Sheet1!H28 -> 0 | H28: =Sheet1!J28 -> 0 | I28: =Sheet1!L28 -> 0 | J28: =Sheet1!N28 -> 0 | K28: =Sheet1!P28 -> 0 | M28: Ống vây khí than sườn hàng 2 | P28: FT03 | Q28: =Sheet1!F62 -> 0 | R28: =Sheet1!H62 -> 0 | S28: =Sheet1!J62 -> 0 | T28: =Sheet1!L62 -> 0 | U28: =Sheet1!N62 -> 0 | V28: =Sheet1!P62 -> 0
E29: 1818 | F29: =Sheet1!F29 -> 0 | G29: =Sheet1!H29 -> 0 | H29: =Sheet1!J29 -> 0 | I29: =Sheet1!L29 -> 0 | J29: =Sheet1!N29 -> 0 | K29: =Sheet1!P29 -> 0 | M29: Ống vây khí than sườn hàng 3 | P29: FT04 | Q29: =Sheet1!F63 -> 0 | R29: =Sheet1!H63 -> 0 | S29: =Sheet1!J63 -> 0 | T29: =Sheet1!L63 -> 0 | U29: =Sheet1!N63 -> 0 | V29: =Sheet1!P63 -> 0
B30: Xả liệu đáy lò | E30: 1403 | F30: =Sheet1!F30 -> 0 | G30: =Sheet1!H30 -> 0 | H30: =Sheet1!J30 -> 0 | I30: =Sheet1!L30 -> 0 | J30: =Sheet1!N30 -> 0 | K30: =Sheet1!P30 -> 0 | M30: Ống vây khí than sườn hàng 4 | P30: FT05 | Q30: =Sheet1!F64 -> 0 | R30: =Sheet1!H64 -> 0 | S30: =Sheet1!J64 -> 0 | T30: =Sheet1!L64 -> 0 | U30: =Sheet1!N64 -> 0 | V30: =Sheet1!P64 -> 0
E31: 1408 | F31: =Sheet1!F31 -> 0 | G31: =Sheet1!H31 -> 0 | H31: =Sheet1!J31 -> 0 | I31: =Sheet1!L31 -> 0 | J31: =Sheet1!N31 -> 0 | K31: =Sheet1!P31 -> 0 | M31: Gió trợ đốt trung tâm | P31: FT06 | Q31: =Sheet1!F65 -> 0 | R31: =Sheet1!H65 -> 0 | S31: =Sheet1!J65 -> 0 | T31: =Sheet1!L65 -> 0 | U31: =Sheet1!N65 -> 0 | V31: =Sheet1!P65 -> 0
E32: 1413 | F32: =Sheet1!F32 -> 0 | G32: =Sheet1!H32 -> 0 | H32: =Sheet1!J32 -> 0 | I32: =Sheet1!L32 -> 0 | J32: =Sheet1!N32 -> 0 | K32: =Sheet1!P32 -> 0 | M32: Gió trợ đốt hàng 1 | P32: FT07 | Q32: =Sheet1!F66 -> 0 | R32: =Sheet1!H66 -> 0 | S32: =Sheet1!J66 -> 0 | T32: =Sheet1!L66 -> 0 | U32: =Sheet1!N66 -> 0 | V32: =Sheet1!P66 -> 0
E33: 1418 | F33: =Sheet1!F33 -> 0 | G33: =Sheet1!H33 -> 0 | H33: =Sheet1!J33 -> 0 | I33: =Sheet1!L33 -> 0 | J33: =Sheet1!N33 -> 0 | K33: =Sheet1!P33 -> 0 | M33: Gió trợ đốt hàng 2 | P33: FT08 | Q33: =Sheet1!F67 -> 0 | R33: =Sheet1!H67 -> 0 | S33: =Sheet1!J67 -> 0 | T33: =Sheet1!L67 -> 0 | U33: =Sheet1!N67 -> 0 | V33: =Sheet1!P67 -> 0
B34: Ống vây gió trợ đốt | E34: 4311 | F34: =Sheet1!F34 -> 0 | G34: =Sheet1!H34 -> 0 | H34: =Sheet1!J34 -> 0 | I34: =Sheet1!L34 -> 0 | J34: =Sheet1!N34 -> 0 | K34: =Sheet1!P34 -> 0 | M34: Gió trợ đốt hàng 3 | P34: FT09 | Q34: =Sheet1!F68 -> 0 | R34: =Sheet1!H68 -> 0 | S34: =Sheet1!J68 -> 0 | T34: =Sheet1!L68 -> 0 | U34: =Sheet1!N68 -> 0 | V34: =Sheet1!P68 -> 0
B35: Bộ trao dổi nhiệt | D35: Khí thải đầu vào | F35: =Sheet1!F35 -> 0 | G35: =Sheet1!H35 -> 0 | H35: =Sheet1!J35 -> 0 | I35: =Sheet1!L35 -> 0 | J35: =Sheet1!N35 -> 0 | K35: =Sheet1!P35 -> 0 | M35: Gió trợ đốt hàng 4 | P35: FT10 | Q35: =Sheet1!F69 -> 0 | R35: =Sheet1!H69 -> 0 | S35: =Sheet1!J69 -> 0 | T35: =Sheet1!L69 -> 0 | U35: =Sheet1!N69 -> 0 | V35: =Sheet1!P69 -> 0
D36: Khí than đầu vào | F36: =Sheet1!F36 -> 0 | G36: =Sheet1!H36 -> 0 | H36: =Sheet1!J36 -> 0 | I36: =Sheet1!L36 -> 0 | J36: =Sheet1!N36 -> 0 | K36: =Sheet1!P36 -> 0 | M36: Ống nhánh khí than trung tâm | O36: 1603 | P36: FT11 | Q36: =Sheet1!F70 -> 0 | R36: =Sheet1!H70 -> 0 | S36: =Sheet1!J70 -> 0 | T36: =Sheet1!L70 -> 0 | U36: =Sheet1!N70 -> 0 | V36: =Sheet1!P70 -> 0
D37: Khí than đầu ra | F37: =Sheet1!F37 -> 0 | G37: =Sheet1!H37 -> 0 | H37: =Sheet1!J37 -> 0 | I37: =Sheet1!L37 -> 0 | J37: =Sheet1!N37 -> 0 | K37: =Sheet1!P37 -> 0 | O37: 1608 | P37: FT12 | Q37: =Sheet1!F71 -> 0 | R37: =Sheet1!H71 -> 0 | S37: =Sheet1!J71 -> 0 | T37: =Sheet1!L71 -> 0 | U37: =Sheet1!N71 -> 0 | V37: =Sheet1!P71 -> 0
B38: Làm mát dầm gió đầu ra | F38: =Sheet1!F38 -> 0 | G38: =Sheet1!H38 -> 0 | H38: =Sheet1!J38 -> 0 | I38: =Sheet1!L38 -> 0 | J38: =Sheet1!N38 -> 0 | K38: =Sheet1!P38 -> 0 | O38: 1613 | P38: FT13 | Q38: =Sheet1!F72 -> 0 | R38: =Sheet1!H72 -> 0 | S38: =Sheet1!J72 -> 0 | T38: =Sheet1!L72 -> 0 | U38: =Sheet1!N72 -> 0 | V38: =Sheet1!P72 -> 0
B39: Bộ lọc bụi | D39: Đầu vào | E39: TE-01 | F39: =Sheet1!F39 -> 0 | G39: =Sheet1!H39 -> 0 | H39: =Sheet1!J39 -> 0 | I39: =Sheet1!L39 -> 0 | J39: =Sheet1!N39 -> 0 | K39: =Sheet1!P39 -> 0 | O39: 1618 | P39: FT14 | Q39: =Sheet1!F73 -> 0 | R39: =Sheet1!H73 -> 0 | S39: =Sheet1!J73 -> 0 | T39: =Sheet1!L73 -> 0 | U39: =Sheet1!N73 -> 0 | V39: =Sheet1!P73 -> 0
D40: Đầu ra | E40: TE-02 | F40: =Sheet1!F40 -> 0 | G40: =Sheet1!H40 -> 0 | H40: =Sheet1!J40 -> 0 | I40: =Sheet1!L40 -> 0 | J40: =Sheet1!N40 -> 0 | K40: =Sheet1!P40 -> 0 | M40: Ống nhánh gió sơ cấp trung tâm | O40: 1603 | P40: FT19 | Q40: =Sheet1!F74 -> 0 | R40: =Sheet1!H74 -> 0 | S40: =Sheet1!J74 -> 0 | T40: =Sheet1!L74 -> 0 | U40: =Sheet1!N74 -> 0 | V40: =Sheet1!P74 -> 0
A41: Độ mở van | B41: Độ mở % van điều tiết gió | G41: Độ mở % van điều tiết khí than | O41: 1608 | P41: FT20 | Q41: =Sheet1!F75 -> 0 | R41: =Sheet1!H75 -> 0 | S41: =Sheet1!J75 -> 0 | T41: =Sheet1!L75 -> 0 | U41: =Sheet1!N75 -> 0 | V41: =Sheet1!P75 -> 0
O42: 1613 | P42: FT21 | Q42: =Sheet1!F76 -> 0 | R42: =Sheet1!H76 -> 0 | S42: =Sheet1!J76 -> 0 | T42: =Sheet1!L76 -> 0 | U42: =Sheet1!N76 -> 0 | V42: =Sheet1!P76 -> 0
...

Sheet Ca Dem
V1: BM.04/QT.05.04
V2: Ngày hiệu lực: 01/01/2024
F4: NHẬT KÝ VẬN HÀNH LÒ VÔI ĐỨNG SỐ 3
A6: Mục | B6: Vị trí đo Thời gian | F6: 8:00 (20:00) | G6: 10:00 (22:00) | H6: 12:00 (0:00) | I6: 14:00 (2:00) | J6: 16:00 (4:00) | K6: 18:00 (6:00) | L6: Mục | M6: Vị trí đo Thời gian | Q6: 8:00 (20:00) | R6: 10:00 (22:00) | S6: 12:00 (0:00) | T6: 14:00 (2:00) | U6: 16:00 (4:00) | V6: 18:00 (6:00)
A7: Nhiệt độ (℃) | B7: Khí thải đỉnh lò | E7: 5404 | F7: =Sheet1!R7 -> 0 | G7: =Sheet1!T7 -> 0 | H7: =Sheet1!V7 -> 0 | I7: =Sheet1!X7 -> 0 | J7: =Sheet1!Z7 -> 0 | K7: =Sheet1!AB7 -> 0 | L7: Áp suất (Kpa) | M7: Ống tổng khí than | P7: PT01 | Q7: =Sheet1!R41 -> 0 | R7: =Sheet1!T41 -> 0 | S7: =Sheet1!V41 -> 0 | T7: =Sheet1!X41 -> 0 | U7: =Sheet1!Z41 -> 0 | V7: =Sheet1!AB41 -> 0
E8: 5408 | F8: =Sheet1!R8 -> 0 | G8: =Sheet1!T8 -> 0 | H8: =Sheet1!V8 -> 0 | I8: =Sheet1!X8 -> 0 | J8: =Sheet1!Z8 -> 0 | K8: =Sheet1!AB8 -> 0 | M8: Ống vây khí than hàng 1 | P8: PT02 | Q8: =Sheet1!R42 -> 0 | R8: =Sheet1!T42 -> 0 | S8: =Sheet1!V42 -> 0 | T8: =Sheet1!X42 -> 0 | U8: =Sheet1!Z42 -> 0 | V8: =Sheet1!AB42 -> 0
E9: 5414 | F9: =Sheet1!R9 -> 0 | G9: =Sheet1!T9 -> 0 | H9: =Sheet1!V9 -> 0 | I9: =Sheet1!X9 -> 0 | J9: =Sheet1!Z9 -> 0 | K9: =Sheet1!AB9 -> 0 | M9: Ống vây khí than hàng 2 | P9: PT03 | Q9: =Sheet1!R43 -> 0 | R9: =Sheet1!T43 -> 0 | S9: =Sheet1!V43 -> 0 | T9: =Sheet1!X43 -> 0 | U9: =Sheet1!Z43 -> 0 | V9: =Sheet1!AB43 -> 0
E10: 5418 | F10: =Sheet1!R10 -> 0 | G10: =Sheet1!T10 -> 0 | H10: =Sheet1!V10 -> 0 | I10: =Sheet1!X10 -> 0 | J10: =Sheet1!Z10 -> 0 | K10: =Sheet1!AB10 -> 0 | M10: Ống vây khí than hàng 3 | P10: PT04 | Q10: =Sheet1!R44 -> 0 | R10: =Sheet1!T44 -> 0 | S10: =Sheet1!V44 -> 0 | T10: =Sheet1!X44 -> 0 | U10: =Sheet1!Z44 -> 0 | V10: =Sheet1!AB44 -> 0
B11: Vùng dự nhiệt | E11: 4405 | F11: =Sheet1!R11 -> 0 | G11: =Sheet1!T11 -> 0 | H11: =Sheet1!V11 -> 0 | I11: =Sheet1!X11 -> 0 | J11: =Sheet1!Z11 -> 0 | K11: =Sheet1!AB11 -> 0 | M11: Ống vây khí than hàng 4 | P11: PT05 | Q11: =Sheet1!R45 -> 0 | R11: =Sheet1!T45 -> 0 | S11: =Sheet1!V45 -> 0 | T11: =Sheet1!X45 -> 0 | U11: =Sheet1!Z45 -> 0 | V11: =Sheet1!AB45 -> 0
E12: 4412 | F12: =Sheet1!R12 -> 0 | G12: =Sheet1!T12 -> 0 | H12: =Sheet1!V12 -> 0 | I12: =Sheet1!X12 -> 0 | J12: =Sheet1!Z12 -> 0 | K12: =Sheet1!AB12 -> 0 | M12: Ống vây khí than trung tâm | P12: PT06 | Q12: =Sheet1!R46 -> 0 | R12: =Sheet1!T46 -> 0 | S12: =Sheet1!V46 -> 0 | T12: =Sheet1!X46 -> 0 | U12: =Sheet1!Z46 -> 0 | V12: =Sheet1!AB46 -> 0
E13: 4420 | F13: =Sheet1!R13 -> 0 | G13: =Sheet1!T13 -> 0 | H13: =Sheet1!V13 -> 0 | I13: =Sheet1!X13 -> 0 | J13: =Sheet1!Z13 -> 0 | K13: =Sheet1!AB13 -> 0 | M13: Ống vây gió trợ đốt hàng 1 | P13: PT07 | Q13: =Sheet1!R47 -> 0 | R13: =Sheet1!T47 -> 0 | S13: =Sheet1!V47 -> 0 | T13: =Sheet1!X47 -> 0 | U13: =Sheet1!Z47 -> 0 | V13: =Sheet1!AB47 -> 0
B14: Biên vùng dự nhiệt | E14: 4402 | F14: =Sheet1!R14 -> 0 | G14: =Sheet1!T14 -> 0 | H14: =Sheet1!V14 -> 0 | I14: =Sheet1!X14 -> 0 | J14: =Sheet1!Z14 -> 0 | K14: =Sheet1!AB14 -> 0 | M14: Ống vây gió trợ đốt hàng 2 | P14: PT08 | Q14: =Sheet1!R48 -> 0 | R14: =Sheet1!T48 -> 0 | S14: =Sheet1!V48 -> 0 | T14: =Sheet1!X48 -> 0 | U14: =Sheet1!Z48 -> 0 | V14: =Sheet1!AB48 -> 0
E15: 4405 | F15: =Sheet1!R15 -> 0 | G15: =Sheet1!T15 -> 0 | H15: =Sheet1!V15 -> 0 | I15: =Sheet1!X15 -> 0 | J15: =Sheet1!Z15 -> 0 | K15: =Sheet1!AB15 -> 0 | M15: Ống vây gió trợ đốt hàng 3 | P15: PT09 | Q15: =Sheet1!R49 -> 0 | R15: =Sheet1!T49 -> 0 | S15: =Sheet1!V49 -> 0 | T15: =Sheet1!X49 -> 0 | U15: =Sheet1!Z49 -> 0 | V15: =Sheet1!AB49 -> 0
E16: 4409 | F16: =Sheet1!R16 -> 0 | G16: =Sheet1!T16 -> 0 | H16: =Sheet1!V16 -> 0 | I16: =Sheet1!X16 -> 0 | J16: =Sheet1!Z16 -> 0 | K16: =Sheet1!AB16 -> 0 | M16: Ống vây gió trợ đốt hàng 4 | P16: PT10 | Q16: =Sheet1!R50 -> 0 | R16: =Sheet1!T50 -> 0 | S16: =Sheet1!V50 -> 0 | T16: =Sheet1!X50 -> 0 | U16: =Sheet1!Z50 -> 0 | V16: =Sheet1!AB50 -> 0
E17: 4412 | F17: =Sheet1!R17 -> 0 | G17: =Sheet1!T17 -> 0 | H17: =Sheet1!V17 -> 0 | I17: =Sheet1!X17 -> 0 | J17: =Sheet1!Z17 -> 0 | K17: =Sheet1!AB17 -> 0 | M17: Ống vây gió trợ đốt trung tâm | P17: PT11 | Q17: =Sheet1!R51 -> 0 | R17: =Sheet1!T51 -> 0 | S17: =Sheet1!V51 -> 0 | T17: =Sheet1!X51 -> 0 | U17: =Sheet1!Z51 -> 0 | V17: =Sheet1!AB51 -> 0
E18: 4415 | F18: =Sheet1!R18 -> 0 | G18: =Sheet1!T18 -> 0 | H18: =Sheet1!V18 -> 0 | I18: =Sheet1!X18 -> 0 | J18: =Sheet1!Z18 -> 0 | K18: =Sheet1!AB18 -> 0 | M18: Áp suất trong lò | P18: PT15 | Q18: =Sheet1!R52 -> 0 | R18: =Sheet1!T52 -> 0 | S18: =Sheet1!V52 -> 0 | T18: =Sheet1!X52 -> 0 | U18: =Sheet1!Z52 -> 0 | V18: =Sheet1!AB52 -> 0
E19: 4419 | F19: =Sheet1!R19 -> 0 | G19: =Sheet1!T19 -> 0 | H19: =Sheet1!V19 -> 0 | I19: =Sheet1!X19 -> 0 | J19: =Sheet1!Z19 -> 0 | K19: =Sheet1!AB19 -> 0 | M19: Ống vây gió điều tiết nhiệt | P19: PT12 | Q19: =Sheet1!R53 -> 0 | R19: =Sheet1!T53 -> 0 | S19: =Sheet1!V53 -> 0 | T19: =Sheet1!X53 -> 0 | U19: =Sheet1!Z53 -> 0 | V19: =Sheet1!AB53 -> 0
B20: Vùng nung | E20: 3201 | F20: =Sheet1!R20 -> 0 | G20: =Sheet1!T20 -> 0 | H20: =Sheet1!V20 -> 0 | I20: =Sheet1!X20 -> 0 | J20: =Sheet1!Z20 -> 0 | K20: =Sheet1!AB20 -> 0 | M20: Gió làm mát đáy lò | P20: PT13 | Q20: =Sheet1!R54 -> 0 | R20: =Sheet1!T54 -> 0 | S20: =Sheet1!V54 -> 0 | T20: =Sheet1!X54 -> 0 | U20: =Sheet1!Z54 -> 0 | V20: =Sheet1!AB54 -> 0
E21: 3203 | F21: =Sheet1!R21 -> 0 | G21: =Sheet1!T21 -> 0 | H21: =Sheet1!V21 -> 0 | I21: =Sheet1!X21 -> 0 | J21: =Sheet1!Z21 -> 0 | K21: =Sheet1!AB21 -> 0 | M21: Ống vây gió làm mát | P21: PT14 | Q21: =Sheet1!R55 -> 0 | R21: =Sheet1!T55 -> 0 | S21: =Sheet1!V55 -> 0 | T21: =Sheet1!X55 -> 0 | U21: =Sheet1!Z55 -> 0 | V21: =Sheet1!AB55 -> 0
E22: 3206 | F22: =Sheet1!R22 -> 0 | G22: =Sheet1!T22 -> 0 | H22: =Sheet1!V22 -> 0 | I22: =Sheet1!X22 -> 0 | J22: =Sheet1!Z22 -> 0 | K22: =Sheet1!AB22 -> 0 | M22: Áp suất quạt trợ đốt | P22: PT17 | Q22: =Sheet1!R56 -> 0 | R22: =Sheet1!T56 -> 0 | S22: =Sheet1!V56 -> 0 | T22: =Sheet1!X56 -> 0 | U22: =Sheet1!Z56 -> 0 | V22: =Sheet1!AB56 -> 0
E23: 3208 | F23: =Sheet1!R23 -> 0 | G23: =Sheet1!T23 -> 0 | H23: =Sheet1!V23 -> 0 | I23: =Sheet1!X23 -> 0 | J23: =Sheet1!Z23 -> 0 | K23: =Sheet1!AB23 -> 0 | M23: Áp suất quạt làm mát | P23: PT18 | Q23: =Sheet1!R57 -> 0 | R23: =Sheet1!T57 -> 0 | S23: =Sheet1!V57 -> 0 | T23: =Sheet1!X57 -> 0 | U23: =Sheet1!Z57 -> 0 | V23: =Sheet1!AB57 -> 0
E24: 3211 | F24: =Sheet1!R24 -> 0 | G24: =Sheet1!T24 -> 0 | H24: =Sheet1!V24 -> 0 | I24: =Sheet1!X24 -> 0 | J24: =Sheet1!Z24 -> 0 | K24: =Sheet1!AB24 -> 0 | M24: Áp đỉnh lò | P24: PT016 | Q24: =Sheet1!R58 -> 0 | R24: =Sheet1!T58 -> 0 | S24: =Sheet1!V58 -> 0 | T24: =Sheet1!X58 -> 0 | U24: =Sheet1!Z58 -> 0 | V24: =Sheet1!AB58 -> 0
E25: 3213 | F25: =Sheet1!R25 -> 0 | G25: =Sheet1!T25 -> 0 | H25: =Sheet1!V25 -> 0 | I25: =Sheet1!X25 -> 0 | J25: =Sheet1!Z25 -> 0 | K25: =Sheet1!AB25 -> 0 | M25: Khí Ni tơ | P25: PT019 | Q25: =Sheet1!R59 -> 0 | R25: =Sheet1!T59 -> 0 | S25: =Sheet1!V59 -> 0 | T25: =Sheet1!X59 -> 0 | U25: =Sheet1!Z59 -> 0 | V25: =Sheet1!AB59 -> 0
E26: 3216 | F26: =Sheet1!R26 -> 0 | G26: =Sheet1!T26 -> 0 | H26: =Sheet1!V26 -> 0 | I26: =Sheet1!X26 -> 0 | J26: =Sheet1!Z26 -> 0 | K26: =Sheet1!AB26 -> 0 | L26: Lưu lượng (m3/h) | M26: Ống khí than trung tâm | P26: FT01 | Q26: =Sheet1!R60 -> 0 | R26: =Sheet1!T60 -> 0 | S26: =Sheet1!V60 -> 0 | T26: =Sheet1!X60 -> 0 | U26: =Sheet1!Z60 -> 0 | V26: =Sheet1!AB60 -> 0
E27: 3218 | F27: =Sheet1!R27 -> 0 | G27: =Sheet1!T27 -> 0 | H27: =Sheet1!V27 -> 0 | I27: =Sheet1!X27 -> 0 | J27: =Sheet1!Z27 -> 0 | K27: =Sheet1!AB27 -> 0 | M27: Ống vây khí than sườn hàng 1 | P27: FT02 | Q27: =Sheet1!R61 -> 0 | R27: =Sheet1!T61 -> 0 | S27: =Sheet1!V61 -> 0 | T27: =Sheet1!X61 -> 0 | U27: =Sheet1!Z61 -> 0 | V27: =Sheet1!AB61 -> 0
B28: Vùng làm mát đáy lò | E28: 1808 | F28: =Sheet1!R28 -> 0 | G28: =Sheet1!T28 -> 0 | H28: =Sheet1!V28 -> 0 | I28: =Sheet1!X28 -> 0 | J28: =Sheet1!Z28 -> 0 | K28: =Sheet1!AB28 -> 0 | M28: Ống vây khí than sườn hàng 2 | P28: FT03 | Q28: =Sheet1!R62 -> 0 | R28: =Sheet1!T62 -> 0 | S28: =Sheet1!V62 -> 0 | T28: =Sheet1!X62 -> 0 | U28: =Sheet1!Z62 -> 0 | V28: =Sheet1!AB62 -> 0
E29: 1818 | F29: =Sheet1!R29 -> 0 | G29: =Sheet1!T29 -> 0 | H29: =Sheet1!V29 -> 0 | I29: =Sheet1!X29 -> 0 | J29: =Sheet1!Z29 -> 0 | K29: =Sheet1!AB29 -> 0 | M29: Ống vây khí than sườn hàng 3 | P29: FT04 | Q29: =Sheet1!R63 -> 0 | R29: =Sheet1!T63 -> 0 | S29: =Sheet1!V63 -> 0 | T29: =Sheet1!X63 -> 0 | U29: =Sheet1!Z63 -> 0 | V29: =Sheet1!AB63 -> 0
B30: Xả liệu đáy lò | E30: 1403 | F30: =Sheet1!R30 -> 0 | G30: =Sheet1!T30 -> 0 | H30: =Sheet1!V30 -> 0 | I30: =Sheet1!X30 -> 0 | J30: =Sheet1!Z30 -> 0 | K30: =Sheet1!AB30 -> 0 | M30: Ống vây khí than sườn hàng 4 | P30: FT05 | Q30: =Sheet1!R64 -> 0 | R30: =Sheet1!T64 -> 0 | S30: =Sheet1!V64 -> 0 | T30: =Sheet1!X64 -> 0 | U30: =Sheet1!Z64 -> 0 | V30: =Sheet1!AB64 -> 0
E31: 1408 | F31: =Sheet1!R31 -> 0 | G31: =Sheet1!T31 -> 0 | H31: =Sheet1!V31 -> 0 | I31: =Sheet1!X31 -> 0 | J31: =Sheet1!Z31 -> 0 | K31: =Sheet1!AB31 -> 0 | M31: Gió trợ đốt trung tâm | P31: FT06 | Q31: =Sheet1!R65 -> 0 | R31: =Sheet1!T65 -> 0 | S31: =Sheet1!V65 -> 0 | T31: =Sheet1!X65 -> 0 | U31: =Sheet1!Z65 -> 0 | V31: =Sheet1!AB65 -> 0
E32: 1413 | F32: =Sheet1!R32 -> 0 | G32: =Sheet1!T32 -> 0 | H32: =Sheet1!V32 -> 0 | I32: =Sheet1!X32 -> 0 | J32: =Sheet1!Z32 -> 0 | K32: =Sheet1!AB32 -> 0 | M32: Gió trợ đốt hàng 1 | P32: FT07 | Q32: =Sheet1!R66 -> 0 | R32: =Sheet1!T66 -> 0 | S32: =Sheet1!V66 -> 0 | T32: =Sheet1!X66 -> 0 | U32: =Sheet1!Z66 -> 0 | V32: =Sheet1!AB66 -> 0
E33: 1418 | F33: =Sheet1!R33 -> 0 | G33: =Sheet1!T33 -> 0 | H33: =Sheet1!V33 -> 0 | I33: =Sheet1!X33 -> 0 | J33: =Sheet1!Z33 -> 0 | K33: =Sheet1!AB33 -> 0 | M33: Gió trợ đốt hàng 2 | P33: FT08 | Q33: =Sheet1!R67 -> 0 | R33: =Sheet1!T67 -> 0 | S33: =Sheet1!V67 -> 0 | T33: =Sheet1!X67 -> 0 | U33: =Sheet1!Z67 -> 0 | V33: =Sheet1!AB67 -> 0
B34: Ống vây gió trợ đốt | E34: 4311 | F34: =Sheet1!R34 -> 0 | G34: =Sheet1!T34 -> 0 | H34: =Sheet1!V34 -> 0 | I34: =Sheet1!X34 -> 0 | J34: =Sheet1!Z34 -> 0 | K34: =Sheet1!AB34 -> 0 | M34: Gió trợ đốt hàng 3 | P34: FT09 | Q34: =Sheet1!R68 -> 0 | R34: =Sheet1!T68 -> 0 | S34: =Sheet1!V68 -> 0 | T34: =Sheet1!X68 -> 0 | U34: =Sheet1!Z68 -> 0 | V34: =Sheet1!AB68 -> 0
B35: Bộ trao dổi nhiệt | D35: Khí thải đầu vào | F35: =Sheet1!R35 -> 0 | G35: =Sheet1!T35 -> 0 | H35: =Sheet1!V35 -> 0 | I35: =Sheet1!X35 -> 0 | J35: =Sheet1!Z35 -> 0 | K35: =Sheet1!AB35 -> 0 | M35: Gió trợ đốt hàng 4 | P35: FT10 | Q35: =Sheet1!R69 -> 0 | R35: =Sheet1!T69 -> 0 | S35: =Sheet1!V69 -> 0 | T35: =Sheet1!X69 -> 0 | U35: =Sheet1!Z69 -> 0 | V35: =Sheet1!AB69 -> 0
D36: Khí than đầu vào | F36: =Sheet1!R36 -> 0 | G36: =Sheet1!T36 -> 0 | H36: =Sheet1!V36 -> 0 | I36: =Sheet1!X36 -> 0 | J36: =Sheet1!Z36 -> 0 | K36: =Sheet1!AB36 -> 0 | M36: Ống nhánh khí than trung tâm | O36: 1603 | P36: FT11 | Q36: =Sheet1!R70 -> 0 | R36: =Sheet1!T70 -> 0 | S36: =Sheet1!V70 -> 0 | T36: =Sheet1!X70 -> 0 | U36: =Sheet1!Z70 -> 0 | V36: =Sheet1!AB70 -> 0
D37: Khí than đầu ra | F37: =Sheet1!R37 -> 0 | G37: =Sheet1!T37 -> 0 | H37: =Sheet1!V37 -> 0 | I37: =Sheet1!X37 -> 0 | J37: =Sheet1!Z37 -> 0 | K37: =Sheet1!AB37 -> 0 | O37: 1608 | P37: FT12 | Q37: =Sheet1!R71 -> 0 | R37: =Sheet1!T71 -> 0 | S37: =Sheet1!V71 -> 0 | T37: =Sheet1!X71 -> 0 | U37: =Sheet1!Z71 -> 0 | V37: =Sheet1!AB71 -> 0
B38: Làm mát dầm gió đầu ra | F38: =Sheet1!R38 -> 0 | G38: =Sheet1!T38 -> 0 | H38: =Sheet1!V38 -> 0 | I38: =Sheet1!X38 -> 0 | J38: =Sheet1!Z38 -> 0 | K38: =Sheet1!AB38 -> 0 | O38: 1613 | P38: FT13 | Q38: =Sheet1!R72 -> 0 | R38: =Sheet1!T72 -> 0 | S38: =Sheet1!V72 -> 0 | T38: =Sheet1!X72 -> 0 | U38: =Sheet1!Z72 -> 0 | V38: =Sheet1!AB72 -> 0
B39: Bộ lọc bụi | D39: Đầu vào | E39: TE-01 | F39: =Sheet1!R39 -> 0 | G39: =Sheet1!T39 -> 0 | H39: =Sheet1!V39 -> 0 | I39: =Sheet1!X39 -> 0 | J39: =Sheet1!Z39 -> 0 | K39: =Sheet1!AB39 -> 0 | O39: 1618 | P39: FT14 | Q39: =Sheet1!R73 -> 0 | R39: =Sheet1!T73 -> 0 | S39: =Sheet1!V73 -> 0 | T39: =Sheet1!X73 -> 0 | U39: =Sheet1!Z73 -> 0 | V39: =Sheet1!AB73 -> 0
D40: Đầu ra | E40: TE-02 | F40: =Sheet1!R40 -> 0 | G40: =Sheet1!T40 -> 0 | H40: =Sheet1!V40 -> 0 | I40: =Sheet1!X40 -> 0 | J40: =Sheet1!Z40 -> 0 | K40: =Sheet1!AB40 -> 0 | M40: Ống nhánh gió sơ cấp trung tâm | O40: 1603 | P40: FT19 | Q40: =Sheet1!R74 -> 0 | R40: =Sheet1!T74 -> 0 | S40: =Sheet1!V74 -> 0 | T40: =Sheet1!X74 -> 0 | U40: =Sheet1!Z74 -> 0 | V40: =Sheet1!AB74 -> 0
A41: Độ mở van | B41: Độ mở % van điều tiết gió | G41: Độ mở % van điều tiết khí than | O41: 1608 | P41: FT20 | Q41: =Sheet1!R75 -> 0 | R41: =Sheet1!T75 -> 0 | S41: =Sheet1!V75 -> 0 | T41: =Sheet1!X75 -> 0 | U41: =Sheet1!Z75 -> 0 | V41: =Sheet1!AB75 -> 0
O42: 1613 | P42: FT21 | Q42: =Sheet1!R76 -> 0 | R42: =Sheet1!T76 -> 0 | S42: =Sheet1!V76 -> 0 | T42: =Sheet1!X76 -> 0 | U42: =Sheet1!Z76 -> 0 | V42: =Sheet1!AB76 -> 0
...
