Workbook

Sheet Sheet1
G1: NHẬT KÝ VẬN HÀNH LÒ VÊ VIÊN Kíp…..…..Từ…...….đến…..….ngày….....tháng ……...năm…..…. | AD1: BM.13/QT.05.03
AD2: Ngày hiệu lực: 01/02/2024
A5: Mục | B5: Vị trí đo/ Thời gian | E5: Kí hiệu | F5: Kí hiệu Wincc | G5: 0.33333333 | H5: 0.375 | I5: 0.41666667 | J5: 0.45833333 | K5: 0.5 | L5: 0.54166667 | M5: 0.58333333 | N5: 0.625 | O5: 0.66666667 | P5: 0.70833333 | Q5: 0.75 | R5: 0.79166667 | S5: 0.83333333 | T5: 0.875 | U5: 0.91666667 | V5: 0.95833333 | W5: 0 | X5: 0.041666667 | Y5: 0.083333333 | Z5: 0.125 | AA5: 0.16666667 | AB5: 0.20833333 | AC5: 0.25 | AD5: 0.29166667
A6: Nhiệt độ (℃) | B6: Máy bản lược | C6: Sấy 1 | D6: Trong khoang | E6: TI651M | F6: TI651M
D7: Hộp gió 1 | E7: TI601M | F7: 2. TI601M
D8: Hộp gió 2 | E8: TI602M | F8: 3. TI602M
D9: Hộp gió 3 | E9: TI603M | F9: 4. TI603M
D10: Hộp gió 4 | E10: TI604M | F10: 5. TI604M
D11: Hộp gió 5 | E11: TI605M | F11: 6. TI605M
D12: Hộp gió 6 | E12: TI606M | F12: 7. TI606M
C13: Sấy 2 | D13: Trong khoang-1 | E13: TI652aM | F13: 8. TI652aM
D14: Trong khoang-2 | E14: TI652bM | F14: 9. TI652bM
D15: Trong khoang-3 | E15: TI652cM | F15: 10. TI652cM
D16: Hộp gió 7 | E16: TI607M | F16: 11. TI607M
D17: Hộp gió 8 | E17: TI608M | F17: 12. TI608M
D18: Hộp gió 9 | E18: TI609M | F18: 13. TI609M
D19: Hộp gió 10 | E19: TI610M | F19: 14. TI610M
D20: Hộp gió 11 | E20: TI611M | F20: 15. TI611M
D21: Hộp gió 12 | E21: TI612M | F21: 16. TI612M
D22: Hộp gió 13 | E22: TI613M | F22: 17. TI613M
D23: Hộp gió 14 | E23: TI614M | F23: 18. TI614M
C24: Dự nhiệt 1 | D24: Trong khoang-1 | E24: TI653aM | F24: 19. TI653aM
D25: Trong khoang-2 | E25: TI653bM | F25: 20. TI653bM
D26: Trong khoang-3 | E26: TI653cM | F26: 21. TI653cM
D27: Hộp gió 15 | E27: TI615M | F27: 22. TI615M
D28: Hộp gió 16 | E28: TI616M | F28: 23. TI616M
D29: Hộp gió 17 | E29: TI617M | F29: 24. TI617M
D30: Hộp gió 18 | E30: TI618M | F30: 25. TI618M
D31: Hộp gió 19 | E31: TI619M | F31: 26. TI619M
D32: Hộp gió 20 | E32: TI620M | F32: 27. TI620M
C33: Dự nhiệt 2 | D33: Trong khoang-1 | E33: TI654aM | F33: 28. TI654aM
D34: Trong khoang-2 | E34: TI654bM | F34: 29. TI654bM
D35: Trong khoang-3 | E35: TI654cM | F35: 30. TI654cM
D36: Trong khoang-4 | E36: TI654dM | F36: 31. TI654dM
D37: Hộp gió 21 | E37: TI621M | F37: 32. TI621M
D38: Hộp gió 22 | E38: TI622M | F38: 33. TI622M
D39: Hộp gió 23 | E39: TI623M | F39: 34. TI623M
D40: Hộp gió 24 | E40: TI624M | F40: 35. TI624M
D41: Hộp gió 25 | E41: TI625M | F41: 36. TI625M
D42: Hộp gió 26 | E42: TI626M | F42: 37. TI626M
...

Sheet Ca ngay
S1: BM.13/QT.05.03
S2: Ngày hiệu lực: 01/02/2024
A5: Mục | B5: Vị trí đo/ Thời gian | E5: Kí hiệu | F5: 0.33333333 | G5: 0.41666667 | H5: 0.5 | I5: 0.58333333 | J5: 0.66666667 | K5: 0.75 | L5: Mục | M5: Vị trí đo/ Thời gian | P5: Kí hiệu | Q5: 0.33333333 | R5: 0.41666667 | S5: 0.5 | T5: 0.58333333 | U5: 0.66666667 | V5: 0.75
A6: Nhiệt độ (℃) | B6: Máy bản lược | C6: Sấy 1 | D6: Trong khoang | E6: TI651M | F6: =Sheet1!G6 -> 0 | G6: =Sheet1!I6 -> 0 | H6: =Sheet1!K6 -> 0 | I6: =Sheet1!M6 -> 0 | J6: =Sheet1!O6 -> 0 | K6: =Sheet1!Q6 -> 0 | L6: Áp suất (Kpa) | M6: Ống khí than LQ lớn | P6: PI701aM | Q6: =Sheet1!G64 -> 0 | R6: =Sheet1!I64 -> 0 | S6: =Sheet1!K64 -> 0 | T6: =Sheet1!M64 -> 0 | U6: =Sheet1!O64 -> 0 | V6: =Sheet1!Q64 -> 0
D7: Hộp gió 1 | E7: TI601M | F7: =Sheet1!G7 -> 0 | G7: =Sheet1!I7 -> 0 | H7: =Sheet1!K7 -> 0 | I7: =Sheet1!M7 -> 0 | J7: =Sheet1!O7 -> 0 | K7: =Sheet1!Q7 -> 0 | M7: Ống khí than LQ nhỏ | P7: PI701bM | Q7: =Sheet1!G65 -> 0 | R7: =Sheet1!I65 -> 0 | S7: =Sheet1!K65 -> 0 | T7: =Sheet1!M65 -> 0 | U7: =Sheet1!O65 -> 0 | V7: =Sheet1!Q65 -> 0
D8: Hộp gió 2 | E8: TI602M | F8: =Sheet1!G8 -> 0 | G8: =Sheet1!I8 -> 0 | H8: =Sheet1!K8 -> 0 | I8: =Sheet1!M8 -> 0 | J8: =Sheet1!O8 -> 0 | K8: =Sheet1!Q8 -> 0 | M8: Ống khí than DN1 | P8: --- | Q8: =Sheet1!G66 -> 0 | R8: =Sheet1!I66 -> 0 | S8: =Sheet1!K66 -> 0 | T8: =Sheet1!M66 -> 0 | U8: =Sheet1!O66 -> 0 | V8: =Sheet1!Q66 -> 0
D9: Hộp gió 3 | E9: TI603M | F9: =Sheet1!G9 -> 0 | G9: =Sheet1!I9 -> 0 | H9: =Sheet1!K9 -> 0 | I9: =Sheet1!M9 -> 0 | J9: =Sheet1!O9 -> 0 | K9: =Sheet1!Q9 -> 0 | M9: Ống gió trợ đốt LQ | P9: PI702M | Q9: =Sheet1!G67 -> 0 | R9: =Sheet1!I67 -> 0 | S9: =Sheet1!K67 -> 0 | T9: =Sheet1!M67 -> 0 | U9: =Sheet1!O67 -> 0 | V9: =Sheet1!Q67 -> 0
D10: Hộp gió 4 | E10: TI604M | F10: =Sheet1!G10 -> 0 | G10: =Sheet1!I10 -> 0 | H10: =Sheet1!K10 -> 0 | I10: =Sheet1!M10 -> 0 | J10: =Sheet1!O10 -> 0 | K10: =Sheet1!Q10 -> 0 | M10: Ống gió trợ đốt DN1 | P10: --- | Q10: =Sheet1!G68 -> 0 | R10: =Sheet1!I68 -> 0 | S10: =Sheet1!K68 -> 0 | T10: =Sheet1!M68 -> 0 | U10: =Sheet1!O68 -> 0 | V10: =Sheet1!Q68 -> 0
D11: Hộp gió 5 | E11: TI605M | F11: =Sheet1!G11 -> 0 | G11: =Sheet1!I11 -> 0 | H11: =Sheet1!K11 -> 0 | I11: =Sheet1!M11 -> 0 | J11: =Sheet1!O11 -> 0 | K11: =Sheet1!Q11 -> 0 | M11: Đầu vào lọc bụi tĩnh điện | P11: PI1001M | Q11: =Sheet1!G69 -> 0 | R11: =Sheet1!I69 -> 0 | S11: =Sheet1!K69 -> 0 | T11: =Sheet1!M69 -> 0 | U11: =Sheet1!O69 -> 0 | V11: =Sheet1!Q69 -> 0
D12: Hộp gió 6 | E12: TI606M | F12: =Sheet1!G12 -> 0 | G12: =Sheet1!I12 -> 0 | H12: =Sheet1!K12 -> 0 | I12: =Sheet1!M12 -> 0 | J12: =Sheet1!O12 -> 0 | K12: =Sheet1!Q12 -> 0 | M12: Đầu ra lọc bụi tĩnh điện | P12: PI1002M | Q12: =Sheet1!G70 -> 0 | R12: =Sheet1!I70 -> 0 | S12: =Sheet1!K70 -> 0 | T12: =Sheet1!M70 -> 0 | U12: =Sheet1!O70 -> 0 | V12: =Sheet1!Q70 -> 0
C13: Sấy 2 | D13: Trong khoang-1 | E13: TI652aM | F13: =Sheet1!G13 -> 0 | G13: =Sheet1!I13 -> 0 | H13: =Sheet1!K13 -> 0 | I13: =Sheet1!M13 -> 0 | J13: =Sheet1!O13 -> 0 | K13: =Sheet1!Q13 -> 0 | M13: Nước đầu vào bản lược số 1 | P13: PI641M | Q13: =Sheet1!G71 -> 0 | R13: =Sheet1!I71 -> 0 | S13: =Sheet1!K71 -> 0 | T13: =Sheet1!M71 -> 0 | U13: =Sheet1!O71 -> 0 | V13: =Sheet1!Q71 -> 0
D14: Trong khoang-2 | E14: TI652bM | F14: =Sheet1!G14 -> 0 | G14: =Sheet1!I14 -> 0 | H14: =Sheet1!K14 -> 0 | I14: =Sheet1!M14 -> 0 | J14: =Sheet1!O14 -> 0 | K14: =Sheet1!Q14 -> 0 | M14: Nước đầu vào bản lược số 2 | P14: PI642M | Q14: =Sheet1!G72 -> 0 | R14: =Sheet1!I72 -> 0 | S14: =Sheet1!K72 -> 0 | T14: =Sheet1!M72 -> 0 | U14: =Sheet1!O72 -> 0 | V14: =Sheet1!Q72 -> 0
D15: Trong khoang-3 | E15: TI652cM | F15: =Sheet1!G15 -> 0 | G15: =Sheet1!I15 -> 0 | H15: =Sheet1!K15 -> 0 | I15: =Sheet1!M15 -> 0 | J15: =Sheet1!O15 -> 0 | K15: =Sheet1!Q15 -> 0 | M15: Nước đầu vào Lò quay số 1 | P15: PI708dM | Q15: =Sheet1!G73 -> 0 | R15: =Sheet1!I73 -> 0 | S15: =Sheet1!K73 -> 0 | T15: =Sheet1!M73 -> 0 | U15: =Sheet1!O73 -> 0 | V15: =Sheet1!Q73 -> 0
D16: Hộp gió 7 | E16: TI607M | F16: =Sheet1!G16 -> 0 | G16: =Sheet1!I16 -> 0 | H16: =Sheet1!K16 -> 0 | I16: =Sheet1!M16 -> 0 | J16: =Sheet1!O16 -> 0 | K16: =Sheet1!Q16 -> 0 | M16: Nước đầu vào Lò quay số 2 | P16: PI708bM | Q16: =Sheet1!G74 -> 0 | R16: =Sheet1!I74 -> 0 | S16: =Sheet1!K74 -> 0 | T16: =Sheet1!M74 -> 0 | U16: =Sheet1!O74 -> 0 | V16: =Sheet1!Q74 -> 0
D17: Hộp gió 8 | E17: TI608M | F17: =Sheet1!G17 -> 0 | G17: =Sheet1!I17 -> 0 | H17: =Sheet1!K17 -> 0 | I17: =Sheet1!M17 -> 0 | J17: =Sheet1!O17 -> 0 | K17: =Sheet1!Q17 -> 0 | M17: Bơm dầu thủy lực 1 | P17: --- | Q17: =Sheet1!G75 -> 0 | R17: =Sheet1!I75 -> 0 | S17: =Sheet1!K75 -> 0 | T17: =Sheet1!M75 -> 0 | U17: =Sheet1!O75 -> 0 | V17: =Sheet1!Q75 -> 0
D18: Hộp gió 9 | E18: TI609M | F18: =Sheet1!G18 -> 0 | G18: =Sheet1!I18 -> 0 | H18: =Sheet1!K18 -> 0 | I18: =Sheet1!M18 -> 0 | J18: =Sheet1!O18 -> 0 | K18: =Sheet1!Q18 -> 0 | M18: Bơm dầu thủy lực 2 | P18: --- | Q18: =Sheet1!G76 -> 0 | R18: =Sheet1!I76 -> 0 | S18: =Sheet1!K76 -> 0 | T18: =Sheet1!M76 -> 0 | U18: =Sheet1!O76 -> 0 | V18: =Sheet1!Q76 -> 0
D19: Hộp gió 10 | E19: TI610M | F19: =Sheet1!G19 -> 0 | G19: =Sheet1!I19 -> 0 | H19: =Sheet1!K19 -> 0 | I19: =Sheet1!M19 -> 0 | J19: =Sheet1!O19 -> 0 | K19: =Sheet1!Q19 -> 0 | M19: Đầu vào lọc bụi đa ống 1 | P19: PI1101M | Q19: =Sheet1!G77 -> 0 | R19: =Sheet1!I77 -> 0 | S19: =Sheet1!K77 -> 0 | T19: =Sheet1!M77 -> 0 | U19: =Sheet1!O77 -> 0 | V19: =Sheet1!Q77 -> 0
D20: Hộp gió 11 | E20: TI611M | F20: =Sheet1!G20 -> 0 | G20: =Sheet1!I20 -> 0 | H20: =Sheet1!K20 -> 0 | I20: =Sheet1!M20 -> 0 | J20: =Sheet1!O20 -> 0 | K20: =Sheet1!Q20 -> 0 | M20: Đầu ra lọc bụi đa ống 1 | P20: PI1102M | Q20: =Sheet1!G78 -> 0 | R20: =Sheet1!I78 -> 0 | S20: =Sheet1!K78 -> 0 | T20: =Sheet1!M78 -> 0 | U20: =Sheet1!O78 -> 0 | V20: =Sheet1!Q78 -> 0
D21: Hộp gió 12 | E21: TI612M | F21: =Sheet1!G21 -> 0 | G21: =Sheet1!I21 -> 0 | H21: =Sheet1!K21 -> 0 | I21: =Sheet1!M21 -> 0 | J21: =Sheet1!O21 -> 0 | K21: =Sheet1!Q21 -> 0 | M21: Đầu vào lọc bụi đa ống 2 | P21: PI1151M | Q21: =Sheet1!G79 -> 0 | R21: =Sheet1!I79 -> 0 | S21: =Sheet1!K79 -> 0 | T21: =Sheet1!M79 -> 0 | U21: =Sheet1!O79 -> 0 | V21: =Sheet1!Q79 -> 0
D22: Hộp gió 13 | E22: TI613M | F22: =Sheet1!G22 -> 0 | G22: =Sheet1!I22 -> 0 | H22: =Sheet1!K22 -> 0 | I22: =Sheet1!M22 -> 0 | J22: =Sheet1!O22 -> 0 | K22: =Sheet1!Q22 -> 0 | M22: Đầu ra lọc bụi đa ống 2 | P22: PI1152M | Q22: =Sheet1!G80 -> 0 | R22: =Sheet1!I80 -> 0 | S22: =Sheet1!K80 -> 0 | T22: =Sheet1!M80 -> 0 | U22: =Sheet1!O80 -> 0 | V22: =Sheet1!Q80 -> 0
D23: Hộp gió 14 | E23: TI614M | F23: =Sheet1!G23 -> 0 | G23: =Sheet1!I23 -> 0 | H23: =Sheet1!K23 -> 0 | I23: =Sheet1!M23 -> 0 | J23: =Sheet1!O23 -> 0 | K23: =Sheet1!Q23 -> 0 | M23: Khoang 2 LMV - DN1 | P23: PI809M | Q23: =Sheet1!G81 -> 0 | R23: =Sheet1!I81 -> 0 | S23: =Sheet1!K81 -> 0 | T23: =Sheet1!M81 -> 0 | U23: =Sheet1!O81 -> 0 | V23: =Sheet1!Q81 -> 0
C24: Dự nhiệt 1 | D24: Trong khoang-1 | E24: TI653aM | F24: =Sheet1!G24 -> 0 | G24: =Sheet1!I24 -> 0 | H24: =Sheet1!K24 -> 0 | I24: =Sheet1!M24 -> 0 | J24: =Sheet1!O24 -> 0 | K24: =Sheet1!Q24 -> 0 | M24: Khoang 3 LMV - Sấy 1 | P24: PI810M | Q24: =Sheet1!G82 -> 0 | R24: =Sheet1!I82 -> 0 | S24: =Sheet1!K82 -> 0 | T24: =Sheet1!M82 -> 0 | U24: =Sheet1!O82 -> 0 | V24: =Sheet1!Q82 -> 0
D25: Trong khoang-2 | E25: TI653bM | F25: =Sheet1!G25 -> 0 | G25: =Sheet1!I25 -> 0 | H25: =Sheet1!K25 -> 0 | I25: =Sheet1!M25 -> 0 | J25: =Sheet1!O25 -> 0 | K25: =Sheet1!Q25 -> 0 | M25: Quạt số 1 LMV | P25: PI801M | Q25: =Sheet1!G83 -> 0 | R25: =Sheet1!I83 -> 0 | S25: =Sheet1!K83 -> 0 | T25: =Sheet1!M83 -> 0 | U25: =Sheet1!O83 -> 0 | V25: =Sheet1!Q83 -> 0
D26: Trong khoang-3 | E26: TI653cM | F26: =Sheet1!G26 -> 0 | G26: =Sheet1!I26 -> 0 | H26: =Sheet1!K26 -> 0 | I26: =Sheet1!M26 -> 0 | J26: =Sheet1!O26 -> 0 | K26: =Sheet1!Q26 -> 0 | M26: Quạt số 2 LMV | P26: PI802M | Q26: =Sheet1!G84 -> 0 | R26: =Sheet1!I84 -> 0 | S26: =Sheet1!K84 -> 0 | T26: =Sheet1!M84 -> 0 | U26: =Sheet1!O84 -> 0 | V26: =Sheet1!Q84 -> 0
D27: Hộp gió 15 | E27: TI615M | F27: =Sheet1!G27 -> 0 | G27: =Sheet1!I27 -> 0 | H27: =Sheet1!K27 -> 0 | I27: =Sheet1!M27 -> 0 | J27: =Sheet1!O27 -> 0 | K27: =Sheet1!Q27 -> 0 | M27: Quạt số 3 LMV | P27: PI803M | Q27: =Sheet1!G85 -> 0 | R27: =Sheet1!I85 -> 0 | S27: =Sheet1!K85 -> 0 | T27: =Sheet1!M85 -> 0 | U27: =Sheet1!O85 -> 0 | V27: =Sheet1!Q85 -> 0
D28: Hộp gió 16 | E28: TI616M | F28: =Sheet1!G28 -> 0 | G28: =Sheet1!I28 -> 0 | H28: =Sheet1!K28 -> 0 | I28: =Sheet1!M28 -> 0 | J28: =Sheet1!O28 -> 0 | K28: =Sheet1!Q28 -> 0 | M28: Quạt số 4 LMV | P28: PI804M | Q28: =Sheet1!G86 -> 0 | R28: =Sheet1!I86 -> 0 | S28: =Sheet1!K86 -> 0 | T28: =Sheet1!M86 -> 0 | U28: =Sheet1!O86 -> 0 | V28: =Sheet1!Q86 -> 0
D29: Hộp gió 17 | E29: TI617M | F29: =Sheet1!G29 -> 0 | G29: =Sheet1!I29 -> 0 | H29: =Sheet1!K29 -> 0 | I29: =Sheet1!M29 -> 0 | J29: =Sheet1!O29 -> 0 | K29: =Sheet1!Q29 -> 0 | M29: Đường ống phun than | P29: PI751bM | Q29: =Sheet1!G87 -> 0 | R29: =Sheet1!I87 -> 0 | S29: =Sheet1!K87 -> 0 | T29: =Sheet1!M87 -> 0 | U29: =Sheet1!O87 -> 0 | V29: =Sheet1!Q87 -> 0
D30: Hộp gió 18 | E30: TI618M | F30: =Sheet1!G30 -> 0 | G30: =Sheet1!I30 -> 0 | H30: =Sheet1!K30 -> 0 | I30: =Sheet1!M30 -> 0 | J30: =Sheet1!O30 -> 0 | K30: =Sheet1!Q30 -> 0 | M30: Đầu lò quay | P30: PI703 | Q30: =Sheet1!G88 -> 0 | R30: =Sheet1!I88 -> 0 | S30: =Sheet1!K88 -> 0 | T30: =Sheet1!M88 -> 0 | U30: =Sheet1!O88 -> 0 | V30: =Sheet1!Q88 -> 0
D31: Hộp gió 19 | E31: TI619M | F31: =Sheet1!G31 -> 0 | G31: =Sheet1!I31 -> 0 | H31: =Sheet1!K31 -> 0 | I31: =Sheet1!M31 -> 0 | J31: =Sheet1!O31 -> 0 | K31: =Sheet1!Q31 -> 0 | M31: Đuôi lò quay | P31: PI704M | Q31: =Sheet1!G89 -> 0 | R31: =Sheet1!I89 -> 0 | S31: =Sheet1!K89 -> 0 | T31: =Sheet1!M89 -> 0 | U31: =Sheet1!O89 -> 0 | V31: =Sheet1!Q89 -> 0
D32: Hộp gió 20 | E32: TI620M | F32: =Sheet1!G32 -> 0 | G32: =Sheet1!I32 -> 0 | H32: =Sheet1!K32 -> 0 | I32: =Sheet1!M32 -> 0 | J32: =Sheet1!O32 -> 0 | K32: =Sheet1!Q32 -> 0 | M32: Can áp số 1 DN 2 | P32: PI654aM | Q32: =Sheet1!G90 -> 0 | R32: =Sheet1!I90 -> 0 | S32: =Sheet1!K90 -> 0 | T32: =Sheet1!M90 -> 0 | U32: =Sheet1!O90 -> 0 | V32: =Sheet1!Q90 -> 0
C33: Dự nhiệt 2 | D33: Trong khoang-1 | E33: TI654aM | F33: =Sheet1!G33 -> 0 | G33: =Sheet1!I33 -> 0 | H33: =Sheet1!K33 -> 0 | I33: =Sheet1!M33 -> 0 | J33: =Sheet1!O33 -> 0 | K33: =Sheet1!Q33 -> 0 | M33: Can áp số 2 DN 2 | P33: PI654bM | Q33: =Sheet1!G91 -> 0 | R33: =Sheet1!I91 -> 0 | S33: =Sheet1!K91 -> 0 | T33: =Sheet1!M91 -> 0 | U33: =Sheet1!O91 -> 0 | V33: =Sheet1!Q91 -> 0
D34: Trong khoang-2 | E34: TI654bM | F34: =Sheet1!G34 -> 0 | G34: =Sheet1!I34 -> 0 | H34: =Sheet1!K34 -> 0 | I34: =Sheet1!M34 -> 0 | J34: =Sheet1!O34 -> 0 | K34: =Sheet1!Q34 -> 0 | M34: Can áp số 3 DN 2 | P34: PI654cM | Q34: =Sheet1!G92 -> 0 | R34: =Sheet1!I92 -> 0 | S34: =Sheet1!K92 -> 0 | T34: =Sheet1!M92 -> 0 | U34: =Sheet1!O92 -> 0 | V34: =Sheet1!Q92 -> 0
D35: Trong khoang-3 | E35: TI654cM | F35: =Sheet1!G35 -> 0 | G35: =Sheet1!I35 -> 0 | H35: =Sheet1!K35 -> 0 | I35: =Sheet1!M35 -> 0 | J35: =Sheet1!O35 -> 0 | K35: =Sheet1!Q35 -> 0 | M35: Can áp số 4 DN 2 | P35: PI654dM | Q35: =Sheet1!G93 -> 0 | R35: =Sheet1!I93 -> 0 | S35: =Sheet1!K93 -> 0 | T35: =Sheet1!M93 -> 0 | U35: =Sheet1!O93 -> 0 | V35: =Sheet1!Q93 -> 0
D36: Trong khoang-4 | E36: TI654dM | F36: =Sheet1!G36 -> 0 | G36: =Sheet1!I36 -> 0 | H36: =Sheet1!K36 -> 0 | I36: =Sheet1!M36 -> 0 | J36: =Sheet1!O36 -> 0 | K36: =Sheet1!Q36 -> 0 | M36: Can áp số 1 DN1 | P36: PI653aM | Q36: =Sheet1!G94 -> 0 | R36: =Sheet1!I94 -> 0 | S36: =Sheet1!K94 -> 0 | T36: =Sheet1!M94 -> 0 | U36: =Sheet1!O94 -> 0 | V36: =Sheet1!Q94 -> 0
D37: Hộp gió 21 | E37: TI621M | F37: =Sheet1!G37 -> 0 | G37: =Sheet1!I37 -> 0 | H37: =Sheet1!K37 -> 0 | I37: =Sheet1!M37 -> 0 | J37: =Sheet1!O37 -> 0 | K37: =Sheet1!Q37 -> 0 | M37: Can áp số 2 DN1 | P37: PI653bM | Q37: =Sheet1!G95 -> 0 | R37: =Sheet1!I95 -> 0 | S37: =Sheet1!K95 -> 0 | T37: =Sheet1!M95 -> 0 | U37: =Sheet1!O95 -> 0 | V37: =Sheet1!Q95 -> 0
D38: Hộp gió 22 | E38: TI622M | F38: =Sheet1!G38 -> 0 | G38: =Sheet1!I38 -> 0 | H38: =Sheet1!K38 -> 0 | I38: =Sheet1!M38 -> 0 | J38: =Sheet1!O38 -> 0 | K38: =Sheet1!Q38 -> 0 | M38: Can áp số 1 Sấy 2 | P38: PI652aM | Q38: =Sheet1!G96 -> 0 | R38: =Sheet1!I96 -> 0 | S38: =Sheet1!K96 -> 0 | T38: =Sheet1!M96 -> 0 | U38: =Sheet1!O96 -> 0 | V38: =Sheet1!Q96 -> 0
D39: Hộp gió 23 | E39: TI623M | F39: =Sheet1!G39 -> 0 | G39: =Sheet1!I39 -> 0 | H39: =Sheet1!K39 -> 0 | I39: =Sheet1!M39 -> 0 | J39: =Sheet1!O39 -> 0 | K39: =Sheet1!Q39 -> 0 | M39: Can áp số 2 Sấy 2 | P39: PI652bM | Q39: =Sheet1!G97 -> 0 | R39: =Sheet1!I97 -> 0 | S39: =Sheet1!K97 -> 0 | T39: =Sheet1!M97 -> 0 | U39: =Sheet1!O97 -> 0 | V39: =Sheet1!Q97 -> 0
D40: Hộp gió 24 | E40: TI624M | F40: =Sheet1!G40 -> 0 | G40: =Sheet1!I40 -> 0 | H40: =Sheet1!K40 -> 0 | I40: =Sheet1!M40 -> 0 | J40: =Sheet1!O40 -> 0 | K40: =Sheet1!Q40 -> 0 | M40: Can áp Sấy 1 | P40: PI651M | Q40: =Sheet1!G98 -> 0 | R40: =Sheet1!I98 -> 0 | S40: =Sheet1!K98 -> 0 | T40: =Sheet1!M98 -> 0 | U40: =Sheet1!O98 -> 0 | V40: =Sheet1!Q98 -> 0
D41: Hộp gió 25 | E41: TI625M | F41: =Sheet1!G41 -> 0 | G41: =Sheet1!I41 -> 0 | H41: =Sheet1!K41 -> 0 | I41: =Sheet1!M41 -> 0 | J41: =Sheet1!O41 -> 0 | K41: =Sheet1!Q41 -> 0 | L41: Lưu lượng (m3/h) | M41: Ống khí than LQ lớn | P41: FI701aM | Q41: =Sheet1!G99 -> 0 | R41: =Sheet1!I99 -> 0 | S41: =Sheet1!K99 -> 0 | T41: =Sheet1!M99 -> 0 | U41: =Sheet1!O99 -> 0 | V41: =Sheet1!Q99 -> 0
D42: Hộp gió 26 | E42: TI626M | F42: =Sheet1!G42 -> 0 | G42: =Sheet1!I42 -> 0 | H42: =Sheet1!K42 -> 0 | I42: =Sheet1!M42 -> 0 | J42: =Sheet1!O42 -> 0 | K42: =Sheet1!Q42 -> 0 | M42: Ống khí than LQ nhỏ | P42: FI701BM | Q42: =Sheet1!G100 -> 0 | R42: =Sheet1!I100 -> 0 | S42: =Sheet1!K100 -> 0 | T42: =Sheet1!M100 -> 0 | U42: =Sheet1!O100 -> 0 | V42: =Sheet1!Q100 -> 0
...

Sheet Ca dem
S1: BM.13/QT.05.03
S2: Ngày hiệu lực: 01/02/2024
A5: Mục | B5: Vị trí đo/ Thời gian | E5: Kí hiệu | F5: 0.83333333 | G5: 0.91666667 | H5: 1 | I5: 1.0833333 | J5: 1.1666667 | K5: 1.25 | L5: Mục | M5: Vị trí đo/ Thời gian | P5: Kí hiệu | Q5: 0.83333333 | R5: 0.91666667 | S5: 1 | T5: 1.0833333 | U5: 1.1666667 | V5: 1.25
A6: Nhiệt độ (℃) | B6: Máy bản lược | C6: Sấy 1 | D6: Trong khoang | E6: TI651M | F6: =Sheet1!S6 -> 0 | G6: =Sheet1!U6 -> 0 | H6: =Sheet1!W6 -> 0 | I6: =Sheet1!Y6 -> 0 | J6: =Sheet1!AA6 -> 0 | K6: =Sheet1!AC6 -> 0 | L6: Áp suất (Kpa) | M6: Ống khí than LQ lớn | P6: PI701aM | Q6: =Sheet1!S64 -> 0 | R6: =Sheet1!U64 -> 0 | S6: =Sheet1!W64 -> 0 | T6: =Sheet1!Y64 -> 0 | U6: =Sheet1!AA64 -> 0 | V6: =Sheet1!AC64 -> 0
D7: Hộp gió 1 | E7: TI601M | F7: =Sheet1!S7 -> 0 | G7: =Sheet1!U7 -> 0 | H7: =Sheet1!W7 -> 0 | I7: =Sheet1!Y7 -> 0 | J7: =Sheet1!AA7 -> 0 | K7: =Sheet1!AC7 -> 0 | M7: Ống khí than LQ nhỏ | P7: PI701bM | Q7: =Sheet1!S65 -> 0 | R7: =Sheet1!U65 -> 0 | S7: =Sheet1!W65 -> 0 | T7: =Sheet1!Y65 -> 0 | U7: =Sheet1!AA65 -> 0 | V7: =Sheet1!AC65 -> 0
D8: Hộp gió 2 | E8: TI602M | F8: =Sheet1!S8 -> 0 | G8: =Sheet1!U8 -> 0 | H8: =Sheet1!W8 -> 0 | I8: =Sheet1!Y8 -> 0 | J8: =Sheet1!AA8 -> 0 | K8: =Sheet1!AC8 -> 0 | M8: Ống khí than DN1 | P8: --- | Q8: =Sheet1!S66 -> 0 | R8: =Sheet1!U66 -> 0 | S8: =Sheet1!W66 -> 0 | T8: =Sheet1!Y66 -> 0 | U8: =Sheet1!AA66 -> 0 | V8: =Sheet1!AC66 -> 0
D9: Hộp gió 3 | E9: TI603M | F9: =Sheet1!S9 -> 0 | G9: =Sheet1!U9 -> 0 | H9: =Sheet1!W9 -> 0 | I9: =Sheet1!Y9 -> 0 | J9: =Sheet1!AA9 -> 0 | K9: =Sheet1!AC9 -> 0 | M9: Ống gió trợ đốt LQ | P9: PI702M | Q9: =Sheet1!S67 -> 0 | R9: =Sheet1!U67 -> 0 | S9: =Sheet1!W67 -> 0 | T9: =Sheet1!Y67 -> 0 | U9: =Sheet1!AA67 -> 0 | V9: =Sheet1!AC67 -> 0
D10: Hộp gió 4 | E10: TI604M | F10: =Sheet1!S10 -> 0 | G10: =Sheet1!U10 -> 0 | H10: =Sheet1!W10 -> 0 | I10: =Sheet1!Y10 -> 0 | J10: =Sheet1!AA10 -> 0 | K10: =Sheet1!AC10 -> 0 | M10: Ống gió trợ đốt DN1 | P10: --- | Q10: =Sheet1!S68 -> 0 | R10: =Sheet1!U68 -> 0 | S10: =Sheet1!W68 -> 0 | T10: =Sheet1!Y68 -> 0 | U10: =Sheet1!AA68 -> 0 | V10: =Sheet1!AC68 -> 0
D11: Hộp gió 5 | E11: TI605M | F11: =Sheet1!S11 -> 0 | G11: =Sheet1!U11 -> 0 | H11: =Sheet1!W11 -> 0 | I11: =Sheet1!Y11 -> 0 | J11: =Sheet1!AA11 -> 0 | K11: =Sheet1!AC11 -> 0 | M11: Đầu vào lọc bụi tĩnh điện | P11: PI1001M | Q11: =Sheet1!S69 -> 0 | R11: =Sheet1!U69 -> 0 | S11: =Sheet1!W69 -> 0 | T11: =Sheet1!Y69 -> 0 | U11: =Sheet1!AA69 -> 0 | V11: =Sheet1!AC69 -> 0
D12: Hộp gió 6 | E12: TI606M | F12: =Sheet1!S12 -> 0 | G12: =Sheet1!U12 -> 0 | H12: =Sheet1!W12 -> 0 | I12: =Sheet1!Y12 -> 0 | J12: =Sheet1!AA12 -> 0 | K12: =Sheet1!AC12 -> 0 | M12: Đầu ra lọc bụi tĩnh điện | P12: PI1002M | Q12: =Sheet1!S70 -> 0 | R12: =Sheet1!U70 -> 0 | S12: =Sheet1!W70 -> 0 | T12: =Sheet1!Y70 -> 0 | U12: =Sheet1!AA70 -> 0 | V12: =Sheet1!AC70 -> 0
C13: Sấy 2 | D13: Trong khoang-1 | E13: TI652aM | F13: =Sheet1!S13 -> 0 | G13: =Sheet1!U13 -> 0 | H13: =Sheet1!W13 -> 0 | I13: =Sheet1!Y13 -> 0 | J13: =Sheet1!AA13 -> 0 | K13: =Sheet1!AC13 -> 0 | M13: Nước đầu vào bản lược số 1 | P13: PI641M | Q13: =Sheet1!S71 -> 0 | R13: =Sheet1!U71 -> 0 | S13: =Sheet1!W71 -> 0 | T13: =Sheet1!Y71 -> 0 | U13: =Sheet1!AA71 -> 0 | V13: =Sheet1!AC71 -> 0
D14: Trong khoang-2 | E14: TI652bM | F14: =Sheet1!S14 -> 0 | G14: =Sheet1!U14 -> 0 | H14: =Sheet1!W14 -> 0 | I14: =Sheet1!Y14 -> 0 | J14: =Sheet1!AA14 -> 0 | K14: =Sheet1!AC14 -> 0 | M14: Nước đầu vào bản lược số 2 | P14: PI642M | Q14: =Sheet1!S72 -> 0 | R14: =Sheet1!U72 -> 0 | S14: =Sheet1!W72 -> 0 | T14: =Sheet1!Y72 -> 0 | U14: =Sheet1!AA72 -> 0 | V14: =Sheet1!AC72 -> 0
D15: Trong khoang-3 | E15: TI652cM | F15: =Sheet1!S15 -> 0 | G15: =Sheet1!U15 -> 0 | H15: =Sheet1!W15 -> 0 | I15: =Sheet1!Y15 -> 0 | J15: =Sheet1!AA15 -> 0 | K15: =Sheet1!AC15 -> 0 | M15: Nước đầu vào Lò quay số 1 | P15: PI708dM | Q15: =Sheet1!S73 -> 0 | R15: =Sheet1!U73 -> 0 | S15: =Sheet1!W73 -> 0 | T15: =Sheet1!Y73 -> 0 | U15: =Sheet1!AA73 -> 0 | V15: =Sheet1!AC73 -> 0
D16: Hộp gió 7 | E16: TI607M | F16: =Sheet1!S16 -> 0 | G16: =Sheet1!U16 -> 0 | H16: =Sheet1!W16 -> 0 | I16: =Sheet1!Y16 -> 0 | J16: =Sheet1!AA16 -> 0 | K16: =Sheet1!AC16 -> 0 | M16: Nước đầu vào Lò quay số 2 | P16: PI708bM | Q16: =Sheet1!S74 -> 0 | R16: =Sheet1!U74 -> 0 | S16: =Sheet1!W74 -> 0 | T16: =Sheet1!Y74 -> 0 | U16: =Sheet1!AA74 -> 0 | V16: =Sheet1!AC74 -> 0
D17: Hộp gió 8 | E17: TI608M | F17: =Sheet1!S17 -> 0 | G17: =Sheet1!U17 -> 0 | H17: =Sheet1!W17 -> 0 | I17: =Sheet1!Y17 -> 0 | J17: =Sheet1!AA17 -> 0 | K17: =Sheet1!AC17 -> 0 | M17: Bơm dầu thủy lực 1 | P17: --- | Q17: =Sheet1!S75 -> 0 | R17: =Sheet1!U75 -> 0 | S17: =Sheet1!W75 -> 0 | T17: =Sheet1!Y75 -> 0 | U17: =Sheet1!AA75 -> 0 | V17: =Sheet1!AC75 -> 0
D18: Hộp gió 9 | E18: TI609M | F18: =Sheet1!S18 -> 0 | G18: =Sheet1!U18 -> 0 | H18: =Sheet1!W18 -> 0 | I18: =Sheet1!Y18 -> 0 | J18: =Sheet1!AA18 -> 0 | K18: =Sheet1!AC18 -> 0 | M18: Bơm dầu thủy lực 2 | P18: --- | Q18: =Sheet1!S76 -> 0 | R18: =Sheet1!U76 -> 0 | S18: =Sheet1!W76 -> 0 | T18: =Sheet1!Y76 -> 0 | U18: =Sheet1!AA76 -> 0 | V18: =Sheet1!AC76 -> 0
D19: Hộp gió 10 | E19: TI610M | F19: =Sheet1!S19 -> 0 | G19: =Sheet1!U19 -> 0 | H19: =Sheet1!W19 -> 0 | I19: =Sheet1!Y19 -> 0 | J19: =Sheet1!AA19 -> 0 | K19: =Sheet1!AC19 -> 0 | M19: Đầu vào lọc bụi đa ống 1 | P19: PI1101M | Q19: =Sheet1!S77 -> 0 | R19: =Sheet1!U77 -> 0 | S19: =Sheet1!W77 -> 0 | T19: =Sheet1!Y77 -> 0 | U19: =Sheet1!AA77 -> 0 | V19: =Sheet1!AC77 -> 0
D20: Hộp gió 11 | E20: TI611M | F20: =Sheet1!S20 -> 0 | G20: =Sheet1!U20 -> 0 | H20: =Sheet1!W20 -> 0 | I20: =Sheet1!Y20 -> 0 | J20: =Sheet1!AA20 -> 0 | K20: =Sheet1!AC20 -> 0 | M20: Đầu ra lọc bụi đa ống 1 | P20: PI1102M | Q20: =Sheet1!S78 -> 0 | R20: =Sheet1!U78 -> 0 | S20: =Sheet1!W78 -> 0 | T20: =Sheet1!Y78 -> 0 | U20: =Sheet1!AA78 -> 0 | V20: =Sheet1!AC78 -> 0
D21: Hộp gió 12 | E21: TI612M | F21: =Sheet1!S21 -> 0 | G21: =Sheet1!U21 -> 0 | H21: =Sheet1!W21 -> 0 | I21: =Sheet1!Y21 -> 0 | J21: =Sheet1!AA21 -> 0 | K21: =Sheet1!AC21 -> 0 | M21: Đầu vào lọc bụi đa ống 2 | P21: PI1151M | Q21: =Sheet1!S79 -> 0 | R21: =Sheet1!U79 -> 0 | S21: =Sheet1!W79 -> 0 | T21: =Sheet1!Y79 -> 0 | U21: =Sheet1!AA79 -> 0 | V21: =Sheet1!AC79 -> 0
D22: Hộp gió 13 | E22: TI613M | F22: =Sheet1!S22 -> 0 | G22: =Sheet1!U22 -> 0 | H22: =Sheet1!W22 -> 0 | I22: =Sheet1!Y22 -> 0 | J22: =Sheet1!AA22 -> 0 | K22: =Sheet1!AC22 -> 0 | M22: Đầu ra lọc bụi đa ống 2 | P22: PI1152M | Q22: =Sheet1!S80 -> 0 | R22: =Sheet1!U80 -> 0 | S22: =Sheet1!W80 -> 0 | T22: =Sheet1!Y80 -> 0 | U22: =Sheet1!AA80 -> 0 | V22: =Sheet1!AC80 -> 0
D23: Hộp gió 14 | E23: TI614M | F23: =Sheet1!S23 -> 0 | G23: =Sheet1!U23 -> 0 | H23: =Sheet1!W23 -> 0 | I23: =Sheet1!Y23 -> 0 | J23: =Sheet1!AA23 -> 0 | K23: =Sheet1!AC23 -> 0 | M23: Khoang 2 LMV - DN1 | P23: PI809M | Q23: =Sheet1!S81 -> 0 | R23: =Sheet1!U81 -> 0 | S23: =Sheet1!W81 -> 0 | T23: =Sheet1!Y81 -> 0 | U23: =Sheet1!AA81 -> 0 | V23: =Sheet1!AC81 -> 0
C24: Dự nhiệt 1 | D24: Trong khoang-1 | E24: TI653aM | F24: =Sheet1!S24 -> 0 | G24: =Sheet1!U24 -> 0 | H24: =Sheet1!W24 -> 0 | I24: =Sheet1!Y24 -> 0 | J24: =Sheet1!AA24 -> 0 | K24: =Sheet1!AC24 -> 0 | M24: Khoang 3 LMV - Sấy 1 | P24: PI810M | Q24: =Sheet1!S82 -> 0 | R24: =Sheet1!U82 -> 0 | S24: =Sheet1!W82 -> 0 | T24: =Sheet1!Y82 -> 0 | U24: =Sheet1!AA82 -> 0 | V24: =Sheet1!AC82 -> 0
D25: Trong khoang-2 | E25: TI653bM | F25: =Sheet1!S25 -> 0 | G25: =Sheet1!U25 -> 0 | H25: =Sheet1!W25 -> 0 | I25: =Sheet1!Y25 -> 0 | J25: =Sheet1!AA25 -> 0 | K25: =Sheet1!AC25 -> 0 | M25: Quạt số 1 LMV | P25: PI801M | Q25: =Sheet1!S83 -> 0 | R25: =Sheet1!U83 -> 0 | S25: =Sheet1!W83 -> 0 | T25: =Sheet1!Y83 -> 0 | U25: =Sheet1!AA83 -> 0 | V25: =Sheet1!AC83 -> 0
D26: Trong khoang-3 | E26: TI653cM | F26: =Sheet1!S26 -> 0 | G26: =Sheet1!U26 -> 0 | H26: =Sheet1!W26 -> 0 | I26: =Sheet1!Y26 -> 0 | J26: =Sheet1!AA26 -> 0 | K26: =Sheet1!AC26 -> 0 | M26: Quạt số 2 LMV | P26: PI802M | Q26: =Sheet1!S84 -> 0 | R26: =Sheet1!U84 -> 0 | S26: =Sheet1!W84 -> 0 | T26: =Sheet1!Y84 -> 0 | U26: =Sheet1!AA84 -> 0 | V26: =Sheet1!AC84 -> 0
D27: Hộp gió 15 | E27: TI615M | F27: =Sheet1!S27 -> 0 | G27: =Sheet1!U27 -> 0 | H27: =Sheet1!W27 -> 0 | I27: =Sheet1!Y27 -> 0 | J27: =Sheet1!AA27 -> 0 | K27: =Sheet1!AC27 -> 0 | M27: Quạt số 3 LMV | P27: PI803M | Q27: =Sheet1!S85 -> 0 | R27: =Sheet1!U85 -> 0 | S27: =Sheet1!W85 -> 0 | T27: =Sheet1!Y85 -> 0 | U27: =Sheet1!AA85 -> 0 | V27: =Sheet1!AC85 -> 0
D28: Hộp gió 16 | E28: TI616M | F28: =Sheet1!S28 -> 0 | G28: =Sheet1!U28 -> 0 | H28: =Sheet1!W28 -> 0 | I28: =Sheet1!Y28 -> 0 | J28: =Sheet1!AA28 -> 0 | K28: =Sheet1!AC28 -> 0 | M28: Quạt số 4 LMV | P28: PI804M | Q28: =Sheet1!S86 -> 0 | R28: =Sheet1!U86 -> 0 | S28: =Sheet1!W86 -> 0 | T28: =Sheet1!Y86 -> 0 | U28: =Sheet1!AA86 -> 0 | V28: =Sheet1!AC86 -> 0
D29: Hộp gió 17 | E29: TI617M | F29: =Sheet1!S29 -> 0 | G29: =Sheet1!U29 -> 0 | H29: =Sheet1!W29 -> 0 | I29: =Sheet1!Y29 -> 0 | J29: =Sheet1!AA29 -> 0 | K29: =Sheet1!AC29 -> 0 | M29: Đường ống phun than | P29: PI751bM | Q29: =Sheet1!S87 -> 0 | R29: =Sheet1!U87 -> 0 | S29: =Sheet1!W87 -> 0 | T29: =Sheet1!Y87 -> 0 | U29: =Sheet1!AA87 -> 0 | V29: =Sheet1!AC87 -> 0
D30: Hộp gió 18 | E30: TI618M | F30: =Sheet1!S30 -> 0 | G30: =Sheet1!U30 -> 0 | H30: =Sheet1!W30 -> 0 | I30: =Sheet1!Y30 -> 0 | J30: =Sheet1!AA30 -> 0 | K30: =Sheet1!AC30 -> 0 | M30: Đầu lò quay | P30: PI703 | Q30: =Sheet1!S88 -> 0 | R30: =Sheet1!U88 -> 0 | S30: =Sheet1!W88 -> 0 | T30: =Sheet1!Y88 -> 0 | U30: =Sheet1!AA88 -> 0 | V30: =Sheet1!AC88 -> 0
D31: Hộp gió 19 | E31: TI619M | F31: =Sheet1!S31 -> 0 | G31: =Sheet1!U31 -> 0 | H31: =Sheet1!W31 -> 0 | I31: =Sheet1!Y31 -> 0 | J31: =Sheet1!AA31 -> 0 | K31: =Sheet1!AC31 -> 0 | M31: Đuôi lò quay | P31: PI704M | Q31: =Sheet1!S89 -> 0 | R31: =Sheet1!U89 -> 0 | S31: =Sheet1!W89 -> 0 | T31: =Sheet1!Y89 -> 0 | U31: =Sheet1!AA89 -> 0 | V31: =Sheet1!AC89 -> 0
D32: Hộp gió 20 | E32: TI620M | F32: =Sheet1!S32 -> 0 | G32: =Sheet1!U32 -> 0 | H32: =Sheet1!W32 -> 0 | I32: =Sheet1!Y32 -> 0 | J32: =Sheet1!AA32 -> 0 | K32: =Sheet1!AC32 -> 0 | M32: Can áp số 1 DN 2 | P32: PI654aM | Q32: =Sheet1!S90 -> 0 | R32: =Sheet1!U90 -> 0 | S32: =Sheet1!W90 -> 0 | T32: =Sheet1!Y90 -> 0 | U32: =Sheet1!AA90 -> 0 | V32: =Sheet1!AC90 -> 0
C33: Dự nhiệt 2 | D33: Trong khoang-1 | E33: TI654aM | F33: =Sheet1!S33 -> 0 | G33: =Sheet1!U33 -> 0 | H33: =Sheet1!W33 -> 0 | I33: =Sheet1!Y33 -> 0 | J33: =Sheet1!AA33 -> 0 | K33: =Sheet1!AC33 -> 0 | M33: Can áp số 2 DN 2 | P33: PI654bM | Q33: =Sheet1!S91 -> 0 | R33: =Sheet1!U91 -> 0 | S33: =Sheet1!W91 -> 0 | T33: =Sheet1!Y91 -> 0 | U33: =Sheet1!AA91 -> 0 | V33: =Sheet1!AC91 -> 0
D34: Trong khoang-2 | E34: TI654bM | F34: =Sheet1!S34 -> 0 | G34: =Sheet1!U34 -> 0 | H34: =Sheet1!W34 -> 0 | I34: =Sheet1!Y34 -> 0 | J34: =Sheet1!AA34 -> 0 | K34: =Sheet1!AC34 -> 0 | M34: Can áp số 3 DN 2 | P34: PI654cM | Q34: =Sheet1!S92 -> 0 | R34: =Sheet1!U92 -> 0 | S34: =Sheet1!W92 -> 0 | T34: =Sheet1!Y92 -> 0 | U34: =Sheet1!AA92 -> 0 | V34: =Sheet1!AC92 -> 0
D35: Trong khoang-3 | E35: TI654cM | F35: =Sheet1!S35 -> 0 | G35: =Sheet1!U35 -> 0 | H35: =Sheet1!W35 -> 0 | I35: =Sheet1!Y35 -> 0 | J35: =Sheet1!AA35 -> 0 | K35: =Sheet1!AC35 -> 0 | M35: Can áp số 4 DN 2 | P35: PI654dM | Q35: =Sheet1!S93 -> 0 | R35: =Sheet1!U93 -> 0 | S35: =Sheet1!W93 -> 0 | T35: =Sheet1!Y93 -> 0 | U35: =Sheet1!AA93 -> 0 | V35: =Sheet1!AC93 -> 0
D36: Trong khoang-4 | E36: TI654dM | F36: =Sheet1!S36 -> 0 | G36: =Sheet1!U36 -> 0 | H36: =Sheet1!W36 -> 0 | I36: =Sheet1!Y36 -> 0 | J36: =Sheet1!AA36 -> 0 | K36: =Sheet1!AC36 -> 0 | M36: Can áp số 1 DN1 | P36: PI653aM | Q36: =Sheet1!S94 -> 0 | R36: =Sheet1!U94 -> 0 | S36: =Sheet1!W94 -> 0 | T36: =Sheet1!Y94 -> 0 | U36: =Sheet1!AA94 -> 0 | V36: =Sheet1!AC94 -> 0
D37: Hộp gió 21 | E37: TI621M | F37: =Sheet1!S37 -> 0 | G37: =Sheet1!U37 -> 0 | H37: =Sheet1!W37 -> 0 | I37: =Sheet1!Y37 -> 0 | J37: =Sheet1!AA37 -> 0 | K37: =Sheet1!AC37 -> 0 | M37: Can áp số 2 DN1 | P37: PI653bM | Q37: =Sheet1!S95 -> 0 | R37: =Sheet1!U95 -> 0 | S37: =Sheet1!W95 -> 0 | T37: =Sheet1!Y95 -> 0 | U37: =Sheet1!AA95 -> 0 | V37: =Sheet1!AC95 -> 0
D38: Hộp gió 22 | E38: TI622M | F38: =Sheet1!S38 -> 0 | G38: =Sheet1!U38 -> 0 | H38: =Sheet1!W38 -> 0 | I38: =Sheet1!Y38 -> 0 | J38: =Sheet1!AA38 -> 0 | K38: =Sheet1!AC38 -> 0 | M38: Can áp số 1 Sấy 2 | P38: PI652aM | Q38: =Sheet1!S96 -> 0 | R38: =Sheet1!U96 -> 0 | S38: =Sheet1!W96 -> 0 | T38: =Sheet1!Y96 -> 0 | U38: =Sheet1!AA96 -> 0 | V38: =Sheet1!AC96 -> 0
D39: Hộp gió 23 | E39: TI623M | F39: =Sheet1!S39 -> 0 | G39: =Sheet1!U39 -> 0 | H39: =Sheet1!W39 -> 0 | I39: =Sheet1!Y39 -> 0 | J39: =Sheet1!AA39 -> 0 | K39: =Sheet1!AC39 -> 0 | M39: Can áp số 2 Sấy 2 | P39: PI652bM | Q39: =Sheet1!S97 -> 0 | R39: =Sheet1!U97 -> 0 | S39: =Sheet1!W97 -> 0 | T39: =Sheet1!Y97 -> 0 | U39: =Sheet1!AA97 -> 0 | V39: =Sheet1!AC97 -> 0
D40: Hộp gió 24 | E40: TI624M | F40: =Sheet1!S40 -> 0 | G40: =Sheet1!U40 -> 0 | H40: =Sheet1!W40 -> 0 | I40: =Sheet1!Y40 -> 0 | J40: =Sheet1!AA40 -> 0 | K40: =Sheet1!AC40 -> 0 | M40: Can áp Sấy 1 | P40: PI651M | Q40: =Sheet1!S98 -> 0 | R40: =Sheet1!U98 -> 0 | S40: =Sheet1!W98 -> 0 | T40: =Sheet1!Y98 -> 0 | U40: =Sheet1!AA98 -> 0 | V40: =Sheet1!AC98 -> 0
D41: Hộp gió 25 | E41: TI625M | F41: =Sheet1!S41 -> 0 | G41: =Sheet1!U41 -> 0 | H41: =Sheet1!W41 -> 0 | I41: =Sheet1!Y41 -> 0 | J41: =Sheet1!AA41 -> 0 | K41: =Sheet1!AC41 -> 0 | L41: Lưu lượng (m3/h) | M41: Ống khí than LQ lớn | P41: FI701aM | Q41: =Sheet1!S99 -> 0 | R41: =Sheet1!U99 -> 0 | S41: =Sheet1!W99 -> 0 | T41: =Sheet1!Y99 -> 0 | U41: =Sheet1!AA99 -> 0 | V41: =Sheet1!AC99 -> 0
D42: Hộp gió 26 | E42: TI626M | F42: =Sheet1!S42 -> 0 | G42: =Sheet1!U42 -> 0 | H42: =Sheet1!W42 -> 0 | I42: =Sheet1!Y42 -> 0 | J42: =Sheet1!AA42 -> 0 | K42: =Sheet1!AC42 -> 0 | M42: Ống khí than LQ nhỏ | P42: FI701BM | Q42: =Sheet1!S100 -> 0 | R42: =Sheet1!U100 -> 0 | S42: =Sheet1!W100 -> 0 | T42: =Sheet1!Y100 -> 0 | U42: =Sheet1!AA100 -> 0 | V42: =Sheet1!AC100 -> 0
...
